Workbook

Sheet Avaliacao_Humana
A1: Avaliação de Requirements Smells — Avaliacao Humana
A2: HU | B2: Descrição | C2: I-1 | D2: I-2 | E2: I-3 | F2: I-4 | G2: I-5 | H2: I_Count | I2: N-1 | J2: N-2 | K2: N-3 | L2: N-4 | M2: N-5 | N2: N_Count | O2: V-1 | P2: V-2 | Q2: V-3 | R2: V-4 | S2: V-5 | T2: V_Count | U2: E-1 | V2: E-2 | W2: E-3 | X2: E-4 | Y2: E-5 | Z2: E_Count | AA2: S-1 | AB2: S-2 | AC2: S-3 | AD2: S-4 | AE2: S-5 | AF2: S_Count | AG2: T-1 | AH2: T-2 | AI2: T-3 | AJ2: T-4 | AK2: T-5 | AL2: T_Count | AM2: Total_Smells | AN2: Nível
A3: HU01 | B3: [Federal Spending] Como usuário, quero que o botão de publicar no FABS seja desativado após clicar, enquanto as derivações acontecem, para que eu não possa clicar múltiplas vezes na mesma submissão. | C3: 0 | D3: 0 | E3: 0 | F3: 0 | G3: 0 | H3: =SUM(C3:G3) -> 0 | I3: 0 | J3: 1 | K3: 0 | L3: 0 | M3: 1 | N3: =SUM(I3:M3) -> 2 | O3: 0 | P3: 0 | Q3: 0 | R3: 0 | S3: 0 | T3: =SUM(O3:S3) -> 0 | U3: 0 | V3: 0 | W3: 0 | X3: 0 | Y3: 0 | Z3: =SUM(U3:Y3) -> 0 | AA3: 0 | AB3: 0 | AC3: 0 | AD3: 0 | AE3: 0 | AF3: =SUM(AA3:AE3) -> 0 | AG3: 1 | AH3: 1 | AI3: 1 | AJ3: 0 | AK3: 0 | AL3: =SUM(AG3:AK3) -> 3 | AM3: =H3+N3+T3+Z3+AF3+AL3 -> 5 | AN3: =IF(AM3=0,"Conforme",IF(AM3<=12,"Atenção","Crítico")) -> Atenção
A4: HU02 | B4: [Federal Spending] Como usuário de agência, quero enviar meus dados com campos cercados por aspas, para que o Excel não remova zeros à esquerda ou à direita. | C4: 0 | D4: 0 | E4: 0 | F4: 0 | G4: 0 | H4: =SUM(C4:G4) -> 0 | I4: 0 | J4: 0 | K4: 1 | L4: 0 | M4: 0 | N4: =SUM(I4:M4) -> 1 | O4: 0 | P4: 0 | Q4: 0 | R4: 0 | S4: 0 | T4: =SUM(O4:S4) -> 0 | U4: 0 | V4: 0 | W4: 0 | X4: 0 | Y4: 0 | Z4: =SUM(U4:Y4) -> 0 | AA4: 0 | AB4: 0 | AC4: 0 | AD4: 0 | AE4: 0 | AF4: =SUM(AA4:AE4) -> 0 | AG4: 1 | AH4: 0 | AI4: 1 | AJ4: 0 | AK4: 0 | AL4: =SUM(AG4:AK4) -> 2 | AM4: =H4+N4+T4+Z4+AF4+AL4 -> 3 | AN4: =IF(AM4=0,"Conforme",IF(AM4<=12,"Atenção","Crítico")) -> Atenção
A5: HU03 | B5: [Federal Spending] Como usuário do site, quero acessar os arquivos publicados pelo FABS, para que eu possa ver os novos arquivos conforme chegam. | C5: 0 | D5: 0 | E5: 1 | F5: 0 | G5: 0 | H5: =SUM(C5:G5) -> 1 | I5: 0 | J5: 0 | K5: 0 | L5: 0 | M5: 0 | N5: =SUM(I5:M5) -> 0 | O5: 0 | P5: 0 | Q5: 0 | R5: 0 | S5: 0 | T5: =SUM(O5:S5) -> 0 | U5: 0 | V5: 0 | W5: 0 | X5: 0 | Y5: 0 | Z5: =SUM(U5:Y5) -> 0 | AA5: 0 | AB5: 0 | AC5: 0 | AD5: 0 | AE5: 0 | AF5: =SUM(AA5:AE5) -> 0 | AG5: 1 | AH5: 0 | AI5: 1 | AJ5: 1 | AK5: 0 | AL5: =SUM(AG5:AK5) -> 3 | AM5: =H5+N5+T5+Z5+AF5+AL5 -> 4 | AN5: =IF(AM5=0,"Conforme",IF(AM5<=12,"Atenção","Crítico")) -> Atenção
A6: HU04 | B6: [Federal Spending] Como usuário da agência, quero receber um erro de arquivo mais útil ao enviar um arquivo com extensão incorreta. | C6: 0 | D6: 0 | E6: 0 | F6: 0 | G6: 0 | H6: =SUM(C6:G6) -> 0 | I6: 0 | J6: 0 | K6: 0 | L6: 0 | M6: 0 | N6: =SUM(I6:M6) -> 0 | O6: 1 | P6: 0 | Q6: 1 | R6: 0 | S6: 0 | T6: =SUM(O6:S6) -> 2 | U6: 0 | V6: 1 | W6: 0 | X6: 0 | Y6: 0 | Z6: =SUM(U6:Y6) -> 1 | AA6: 0 | AB6: 0 | AC6: 0 | AD6: 0 | AE6: 0 | AF6: =SUM(AA6:AE6) -> 0 | AG6: 1 | AH6: 1 | AI6: 0 | AJ6: 0 | AK6: 0 | AL6: =SUM(AG6:AK6) -> 2 | AM6: =H6+N6+T6+Z6+AF6+AL6 -> 5 | AN6: =IF(AM6=0,"Conforme",IF(AM6<=12,"Atenção","Crítico")) -> Atenção
A7: HU05 | B7: [Federal Spending] Como desenvolvedor, quero que as requisições de geração de arquivos D sejam gerenciadas e armazenadas em cache, para que requisições duplicadas não causem problemas de desempenho. | C7: 0 | D7: 0 | E7: 0 | F7: 0 | G7: 0 | H7: 1 | I7: 1 | J7: 0 | K7: 0 | L7: 1 | M7: 0 | N7: =SUM(I7:M7) -> 2 | O7: 0 | P7: 1 | Q7: 0 | R7: 0 | S7: 0 | T7: =SUM(O7:S7) -> 1 | U7: 0 | V7: 0 | W7: 1 | X7: 0 | Y7: 0 | Z7: =SUM(U7:Y7) -> 1 | AA7: 0 | AB7: 0 | AC7: 0 | AD7: 0 | AE7: 0 | AF7: =SUM(AA7:AE7) -> 0 | AG7: 1 | AH7: 1 | AI7: 1 | AJ7: 0 | AK7: 0 | AL7: =SUM(AG7:AK7) -> 3 | AM7: =H7+N7+T7+Z7+AF7+AL7 -> 8 | AN7: =IF(AM7=0,"Conforme",IF(AM7<=12,"Atenção","Crítico")) -> Atenção
A8: HU06 | B8: [Federal Spending] Como usuário de agência, quero incluir um grande número de campos flexíveis sem impacto no desempenho. | C8: 0 | D8: 0 | E8: 0 | F8: 0 | G8: 0 | H8: =SUM(C8:G8) -> 0 | I8: 0 | J8: 0 | K8: 0 | L8: 0 | M8: 0 | N8: =SUM(I8:M8) -> 0 | O8: 0 | P8: 0 | Q8: 0 | R8: 0 | S8: 0 | T8: =SUM(O8:S8) -> 0 | U8: 1 | V8: 0 | W8: 1 | X8: 0 | Y8: 1 | Z8: =SUM(U8:Y8) -> 3 | AA8: 0 | AB8: 0 | AC8: 0 | AD8: 0 | AE8: 0 | AF8: =SUM(AA8:AE8) -> 0 | AG8: 1 | AH8: 1 | AI8: 0 | AJ8: 0 | AK8: 0 | AL8: =SUM(AG8:AK8) -> 2 | AM8: =H8+N8+T8+Z8+AF8+AL8 -> 5 | AN8: =IF(AM8=0,"Conforme",IF(AM8<=12,"Atenção","Crítico")) -> Atenção
A9: HU07 | B9: [Federal Spending] Como desenvolvedor, quero atualizar a tabela de regras de validação do Broker para contemplar as atualizações de regras do DB-2213. | C9: 1 | D9: 0 | E9: 0 | F9: 0 | G9: 0 | H9: =SUM(C9:G9) -> 1 | I9: 0 | J9: 0 | K9: 0 | L9: 0 | M9: 0 | N9: =SUM(I9:M9) -> 0 | O9: 1 | P9: 0 | Q9: 0 | R9: 0 | S9: 0 | T9: =SUM(O9:S9) -> 1 | U9: 0 | V9: 0 | W9: 0 | X9: 0 | Y9: 0 | Z9: =SUM(U9:Y9) -> 0 | AA9: 0 | AB9: 0 | AC9: 0 | AD9: 0 | AE9: 0 | AF9: =SUM(AA9:AE9) -> 0 | AG9: 1 | AH9: 0 | AI9: 1 | AJ9: 0 | AK9: 0 | AL9: =SUM(AG9:AK9) -> 2 | AM9: =H9+N9+T9+Z9+AF9+AL9 -> 4 | AN9: =IF(AM9=0,"Conforme",IF(AM9<=12,"Atenção","Crítico")) -> Atenção
A10: HU08 | B10: [Federal Spending] Como usuário do site, quero ver dados de assistência financeira atualizados diariamente. | C10: 0 | D10: 0 | E10: 0 | F10: 0 | G10: 0 | H10: =SUM(C10:G10) -> 0 | I10: 0 | J10: 0 | K10: 0 | L10: 0 | M10: 0 | N10: =SUM(I10:M10) -> 0 | O10: 1 | P10: 0 | Q10: 0 | R10: 0 | S10: 0 | T10: =SUM(O10:S10) -> 1 | U10: 0 | V10: 0 | W10: 0 | X10: 0 | Y10: 0 | Z10: =SUM(U10:Y10) -> 0 | AA10: 0 | AB10: 0 | AC10: 0 | AD10: 0 | AE10: 0 | AF10: =SUM(AA10:AE10) -> 0 | AG10: 1 | AH10: 0 | AI10: 0 | AJ10: 1 | AK10: 0 | AL10: =SUM(AG10:AK10) -> 2 | AM10: =H10+N10+T10+Z10+AF10+AL10 -> 3 | AN10: =IF(AM10=0,"Conforme",IF(AM10<=12,"Atenção","Crítico")) -> Atenção
A11: HU09 | B11: [Federal Spending] Como proprietário, quero garantir que o USAspending envie apenas registros de concessão ao meu sistema. | C11: 0 | D11: 0 | E11: 1 | F11: 1 | G11: 0 | H11: =SUM(C11:G11) -> 2 | I11: 0 | J11: 0 | K11: 0 | L11: 0 | M11: 0 | N11: =SUM(I11:M11) -> 0 | O11: 1 | P11: 0 | Q11: 0 | R11: 0 | S11: 0 | T11: =SUM(O11:S11) -> 1 | U11: 1 | V11: 0 | W11: 0 | X11: 0 | Y11: 0 | Z11: =SUM(U11:Y11) -> 1 | AA11: 0 | AB11: 0 | AC11: 0 | AD11: 0 | AE11: 0 | AF11: =SUM(AA11:AE11) -> 0 | AG11: 1 | AH11: 0 | AI11: 1 | AJ11: 0 | AK11: 0 | AL11: =SUM(AG11:AK11) -> 2 | AM11: =H11+N11+T11+Z11+AF11+AL11 -> 6 | AN11: =IF(AM11=0,"Conforme",IF(AM11<=12,"Atenção","Crítico")) -> Atenção
A12: HU10 | B12: [Federal Spending] Como usuário do broker, quero ajudar a criar mockups de conteúdo, para que eu possa enviar meus dados eficientemente. | C12: 0 | D12: 0 | E12: 0 | F12: 0 | G12: 0 | H12: =SUM(C12:G12) -> 0 | I12: 1 | J12: 0 | K12: 0 | L12: 0 | M12: 0 | N12: =SUM(I12:M12) -> 1 | O12: 0 | P12: 0 | Q12: 1 | R12: 0 | S12: 0 | T12: =SUM(O12:S12) -> 1 | U12: 0 | V12: 1 | W12: 0 | X12: 0 | Y12: 0 | Z12: =SUM(U12:Y12) -> 1 | AA12: 0 | AB12: 0 | AC12: 0 | AD12: 0 | AE12: 0 | AF12: =SUM(AA12:AE12) -> 0 | AG12: 1 | AH12: 1 | AI12: 0 | AJ12: 0 | AK12: 0 | AL12: =SUM(AG12:AK12) -> 2 | AM12: =H12+N12+T12+Z12+AF12+AL12 -> 5 | AN12: =IF(AM12=0,"Conforme",IF(AM12<=12,"Atenção","Crítico")) -> Atenção
A13: HU11 | B13: [Recycling] Como usuário, quero inserir meu CEP e obter uma lista de instalações de reciclagem próximas, para que eu possa decidir quais considerar. | C13: 0 | D13: 0 | E13: 0 | F13: 0 | G13: 0 | H13: =SUM(C13:G13) -> 0 | I13: 0 | J13: 0 | K13: 0 | L13: 0 | M13: 0 | N13: =SUM(I13:M13) -> 0 | O13: 0 | P13: 0 | Q13: 0 | R13: 0 | S13: 0 | T13: =SUM(O13:S13) -> 0 | U13: 1 | V13: 0 | W13: 0 | X13: 0 | Y13: 0 | Z13: =SUM(U13:Y13) -> 1 | AA13: 1 | AB13: 0 | AC13: 0 | AD13: 0 | AE13: 0 | AF13: =SUM(AA13:AE13) -> 1 | AG13: 1 | AH13: 1 | AI13: 1 | AJ13: 1 | AK13: 0 | AL13: =SUM(AG13:AK13) -> 4 | AM13: =H13+N13+T13+Z13+AF13+AL13 -> 6 | AN13: =IF(AM13=0,"Conforme",IF(AM13<=12,"Atenção","Crítico")) -> Atenção
A14: HU12 | B14: [Recycling] Como usuário, quero obter o horário de funcionamento de cada instalação de reciclagem, para que eu possa agendar entregas em meus dias de folga ou após o trabalho. | C14: 0 | D14: 0 | E14: 0 | F14: 0 | G14: 0 | H14: =SUM(C14:G14) -> 0 | I14: 0 | J14: 0 | K14: 0 | L14: 0 | M14: 0 | N14: =SUM(I14:M14) -> 0 | O14: 0 | P14: 0 | Q14: 0 | R14: 0 | S14: 0 | T14: =SUM(O14:S14) -> 0 | U14: 0 | V14: 0 | W14: 0 | X14: 0 | Y14: 0 | Z14: =SUM(U14:Y14) -> 0 | AA14: 0 | AB14: 0 | AC14: 0 | AD14: 0 | AE14: 0 | AF14: =SUM(AA14:AE14) -> 0 | AG14: 1 | AH14: 0 | AI14: 1 | AJ14: 1 | AK14: 0 | AL14: =SUM(AG14:AK14) -> 3 | AM14: =H14+N14+T14+Z14+AF14+AL14 -> 3 | AN14: =IF(AM14=0,"Conforme",IF(AM14<=12,"Atenção","Crítico")) -> Atenção
A15: HU13 | B15: [Recycling] Como administrador, quero adicionar ou remover informações de instalações de reciclagem, para que os usuários recebam as informações mais recentes. | C15: 0 | D15: 0 | E15: 0 | F15: 0 | G15: 0 | H15: =SUM(C15:G15) -> 0 | I15: 0 | J15: 0 | K15: 0 | L15: 0 | M15: 0 | N15: =SUM(I15:M15) -> 0 | O15: 0 | P15: 0 | Q15: 0 | R15: 0 | S15: 0 | T15: =SUM(O15:S15) -> 0 | U15: 0 | V15: 0 | W15: 0 | X15: 0 | Y15: 0 | Z15: =SUM(U15:Y15) -> 0 | AA15: 1 | AB15: 1 | AC15: 0 | AD15: 0 | AE15: 0 | AF15: =SUM(AA15:AE15) -> 2 | AG15: 1 | AH15: 0 | AI15: 1 | AJ15: 0 | AK15: 0 | AL15: =SUM(AG15:AK15) -> 2 | AM15: =H15+N15+T15+Z15+AF15+AL15 -> 4 | AN15: =IF(AM15=0,"Conforme",IF(AM15<=12,"Atenção","Crítico")) -> Atenção
A16: HU14 | B16: [Recycling] Como representante de instalação de reciclagem, quero atualizar minhas informações e os tipos de material que aceito, para evitar falhas de comunicação com os usuários. | C16: 0 | D16: 0 | E16: 0 | F16: 0 | G16: 0 | H16: =SUM(C16:G16) -> 0 | I16: 0 | J16: 0 | K16: 0 | L16: 0 | M16: 0 | N16: =SUM(I16:M16) -> 0 | O16: 0 | P16: 0 | Q16: 0 | R16: 0 | S16: 0 | T16: =SUM(O16:S16) -> 0 | U16: 0 | V16: 0 | W16: 0 | X16: 0 | Y16: 0 | Z16: =SUM(U16:Y16) -> 0 | AA16: 1 | AB16: 0 | AC16: 0 | AD16: 1 | AE16: 0 | AF16: =SUM(AA16:AE16) -> 2 | AG16: 1 | AH16: 0 | AI16: 1 | AJ16: 0 | AK16: 0 | AL16: =SUM(AG16:AK16) -> 2 | AM16: =H16+N16+T16+Z16+AF16+AL16 -> 4 | AN16: =IF(AM16=0,"Conforme",IF(AM16<=12,"Atenção","Crítico")) -> Atenção
A17: HU15 | B17: [Recycling] Como usuário, quero ver todos os locais de centros de reciclagem em um mapa, para verificar quais rotas tomar para descartar resíduos. | C17: 0 | D17: 0 | E17: 0 | F17: 0 | G17: 0 | H17: =SUM(C17:G17) -> 0 | I17: 0 | J17: 0 | K17: 0 | L17: 0 | M17: 0 | N17: =SUM(I17:M17) -> 0 | O17: 0 | P17: 0 | Q17: 0 | R17: 0 | S17: 0 | T17: =SUM(O17:S17) -> 0 | U17: 1 | V17: 0 | W17: 0 | X17: 0 | Y17: 0 | Z17: =SUM(U17:Y17) -> 1 | AA17: 0 | AB17: 0 | AC17: 0 | AD17: 0 | AE17: 0 | AF17: =SUM(AA17:AE17) -> 0 | AG17: 1 | AH17: 0 | AI17: 1 | AJ17: 0 | AK17: 1 | AL17: =SUM(AG17:AK17) -> 3 | AM17: =H17+N17+T17+Z17+AF17+AL17 -> 4 | AN17: =IF(AM17=0,"Conforme",IF(AM17<=12,"Atenção","Crítico")) -> Atenção
A18: HU16 | B18: [Recycling] Como usuário, quero receber recompensas atraentes, para ter um motivo para usar o site. | C18: 0 | D18: 0 | E18: 0 | F18: 0 | G18: 0 | H18: =SUM(C18:G18) -> 0 | I18: 0 | J18: 0 | K18: 1 | L18: 0 | M18: 0 | N18: =SUM(I18:M18) -> 1 | O18: 0 | P18: 1 | Q18: 1 | R18: 0 | S18: 0 | T18: =SUM(O18:S18) -> 2 | U18: 0 | V18: 0 | W18: 0 | X18: 0 | Y18: 0 | Z18: =SUM(U18:Y18) -> 0 | AA18: 0 | AB18: 0 | AC18: 0 | AD18: 0 | AE18: 0 | AF18: =SUM(AA18:AE18) -> 0 | AG18: 1 | AH18: 1 | AI18: 0 | AJ18: 0 | AK18: 0 | AL18: =SUM(AG18:AK18) -> 2 | AM18: =H18+N18+T18+Z18+AF18+AL18 -> 5 | AN18: =IF(AM18=0,"Conforme",IF(AM18<=12,"Atenção","Crítico")) -> Atenção
A19: HU17 | B19: [Recycling] Como administrador, quero visualizar um painel com estatísticas de uso e localizações, para identificar bairros com maior número de descartes. | C19: 0 | D19: 0 | E19: 0 | F19: 0 | G19: 0 | H19: =SUM(C19:G19) -> 0 | I19: 0 | J19: 0 | K19: 0 | L19: 0 | M19: 0 | N19: =SUM(I19:M19) -> 0 | O19: 0 | P19: 0 | Q19: 0 | R19: 0 | S19: 0 | T19: =SUM(O19:S19) -> 0 | U19: 0 | V19: 0 | W19: 0 | X19: 0 | Y19: 0 | Z19: =SUM(U19:Y19) -> 0 | AA19: 1 | AB19: 0 | AC19: 0 | AD19: 0 | AE19: 0 | AF19: =SUM(AA19:AE19) -> 1 | AG19: 1 | AH19: 1 | AI19: 0 | AJ19: 0 | AK19: 1 | AL19: =SUM(AG19:AK19) -> 3 | AM19: =H19+N19+T19+Z19+AF19+AL19 -> 4 | AN19: =IF(AM19=0,"Conforme",IF(AM19<=12,"Atenção","Crítico")) -> Atenção
... A31: HU29 | B31: [Planning Poker] Como desenvolvedor, quero ter criado índices no banco de dados, para que as consultas rodem o mais rápido possível. | C31: 0 | D31: 0 | E31: 0 | F31: 0 | G31: 0 | H31: =SUM(C31:G31) -> 0 | I31: 1 | J31: 0 | K31: 0 | L31: 0 | M31: 0 | N31: =SUM(I31:M31) -> 1 | O31: 0 | P31: 1 | Q31: 0 | R31: 0 | S31: 1 | T31: =SUM(O31:S31) -> 2 | U31: 0 | V31: 1 | W31: 0 | X31: 0 | Y31: 0 | Z31: =SUM(U31:Y31) -> 1 | AA31: 0 | AB31: 0 | AC31: 0 | AD31: 0 | AE31: 0 | AF31: =SUM(AA31:AE31) -> 0 | AG31: 1 | AH31: 0 | AI31: 0 | AJ31: 0 | AK31: 0 | AL31: =SUM(AG31:AK31) -> 1 | AM31: =H31+N31+T31+Z31+AF31+AL31 -> 5 | AN31: =IF(AM31=0,"Conforme",IF(AM31<=12,"Atenção","Crítico")) -> Atenção
A32: HU30 | B32: [Planning Poker] Como Mike, quero ver algumas métricas sobre o uso do jogo, para ver o quanto ele está sendo utilizado. | C32: 0 | D32: 0 | E32: 0 | F32: 0 | G32: 0 | H32: =SUM(C32:G32) -> 0 | I32: 0 | J32: 0 | K32: 0 | L32: 0 | M32: 0 | N32: =SUM(I32:M32) -> 0 | O32: 0 | P32: 0 | Q32: 0 | R32: 0 | S32: 1 | T32: =SUM(O32:S32) -> 1 | U32: 1 | V32: 0 | W32: 1 | X32: 0 | Y32: 0 | Z32: =SUM(U32:Y32) -> 2 | AA32: 0 | AB32: 0 | AC32: 0 | AD32: 0 | AE32: 0 | AF32: =SUM(AA32:AE32) -> 0 | AG32: 1 | AH32: 1 | AI32: 0 | AJ32: 0 | AK32: 0 | AL32: 2 | AM32: =H32+N32+T32+Z32+AF32+AL32 -> 5 | AN32: =IF(AM32=0,"Conforme",IF(AM32<=12,"Atenção","Crítico")) -> Atenção

Sheet ChatGPT_ZeroShot
A1: Avaliação de Requirements Smells — ChatGPT ZeroShot
A2: HU | B2: Descrição | C2: I-1 | D2: I-2 | E2: I-3 | F2: I-4 | G2: I-5 | H2: I_Count | I2: N-1 | J2: N-2 | K2: N-3 | L2: N-4 | M2: N-5 | N2: N_Count | O2: V-1 | P2: V-2 | Q2: V-3 | R2: V-4 | S2: V-5 | T2: V_Count | U2: E-1 | V2: E-2 | W2: E-3 | X2: E-4 | Y2: E-5 | Z2: E_Count | AA2: S-1 | AB2: S-2 | AC2: S-3 | AD2: S-4 | AE2: S-5 | AF2: S_Count | AG2: T-1 | AH2: T-2 | AI2: T-3 | AJ2: T-4 | AK2: T-5 | AL2: T_Count | AM2: Total_Smells | AN2: Nível
A3: HU01 | B3: [Federal Spending] Como usuário, quero que o botão de publicar no FABS seja desativado após clicar, enquanto as derivações acontecem, para que eu não possa clicar múltiplas vezes na mesma submissão. | C3: 0 | D3: 0 | E3: 1 | F3: 0 | G3: 0 | H3: =SUM(C3:G3) -> 1 | I3: 0 | J3: 1 | K3: 0 | L3: 0 | M3: 0 | N3: =SUM(I3:M3) -> 1 | O3: 0 | P3: 0 | Q3: 0 | R3: 0 | S3: 0 | T3: =SUM(O3:S3) -> 0 | U3: 0 | V3: 0 | W3: 0 | X3: 0 | Y3: 0 | Z3: =SUM(U3:Y3) -> 0 | AA3: 0 | AB3: 0 | AC3: 0 | AD3: 0 | AE3: 0 | AF3: =SUM(AA3:AE3) -> 0 | AG3: 1 | AH3: 0 | AI3: 1 | AJ3: 1 | AK3: 1 | AL3: =SUM(AG3:AK3) -> 4 | AM3: =H3+N3+T3+Z3+AF3+AL3 -> 6 | AN3: =IF(AM3=0,"Conforme",IF(AM3<=12,"Atenção","Crítico")) -> Atenção
A4: HU02 | B4: [Federal Spending] Como usuário de agência, quero enviar meus dados com campos cercados por aspas, para que o Excel não remova zeros à esquerda ou à direita. | C4: 0 | D4: 0 | E4: 0 | F4: 0 | G4: 0 | H4: =SUM(C4:G4) -> 0 | I4: 0 | J4: 0 | K4: 1 | L4: 0 | M4: 0 | N4: =SUM(I4:M4) -> 1 | O4: 0 | P4: 0 | Q4: 0 | R4: 0 | S4: 0 | T4: =SUM(O4:S4) -> 0 | U4: 0 | V4: 0 | W4: 0 | X4: 0 | Y4: 0 | Z4: =SUM(U4:Y4) -> 0 | AA4: 0 | AB4: 0 | AC4: 0 | AD4: 0 | AE4: 0 | AF4: =SUM(AA4:AE4) -> 0 | AG4: 1 | AH4: 0 | AI4: 1 | AJ4: 1 | AK4: 1 | AL4: =SUM(AG4:AK4) -> 4 | AM4: =H4+N4+T4+Z4+AF4+AL4 -> 5 | AN4: =IF(AM4=0,"Conforme",IF(AM4<=12,"Atenção","Crítico")) -> Atenção
A5: HU03 | B5: [Federal Spending] Como usuário do site, quero acessar os arquivos publicados pelo FABS, para que eu possa ver os novos arquivos conforme chegam. | C5: 0 | D5: 0 | E5: 1 | F5: 0 | G5: 0 | H5: =SUM(C5:G5) -> 1 | I5: 0 | J5: 0 | K5: 0 | L5: 0 | M5: 0 | N5: =SUM(I5:M5) -> 0 | O5: 0 | P5: 0 | Q5: 0 | R5: 0 | S5: 0 | T5: =SUM(O5:S5) -> 0 | U5: 0 | V5: 0 | W5: 1 | X5: 0 | Y5: 0 | Z5: =SUM(U5:Y5) -> 1 | AA5: 0 | AB5: 0 | AC5: 0 | AD5: 0 | AE5: 0 | AF5: =SUM(AA5:AE5) -> 0 | AG5: 1 | AH5: 0 | AI5: 1 | AJ5: 1 | AK5: 1 | AL5: =SUM(AG5:AK5) -> 4 | AM5: =H5+N5+T5+Z5+AF5+AL5 -> 6 | AN5: =IF(AM5=0,"Conforme",IF(AM5<=12,"Atenção","Crítico")) -> Atenção
A6: HU04 | B6: [Federal Spending] Como usuário da agência, quero receber um erro de arquivo mais útil ao enviar um arquivo com extensão incorreta. | C6: 0 | D6: 0 | E6: 0 | F6: 0 | G6: 0 | H6: =SUM(C6:G6) -> 0 | I6: 0 | J6: 0 | K6: 0 | L6: 0 | M6: 0 | N6: =SUM(I6:M6) -> 0 | O6: 1 | P6: 0 | Q6: 0 | R6: 0 | S6: 0 | T6: =SUM(O6:S6) -> 1 | U6: 1 | V6: 0 | W6: 0 | X6: 0 | Y6: 0 | Z6: =SUM(U6:Y6) -> 1 | AA6: 0 | AB6: 0 | AC6: 0 | AD6: 0 | AE6: 0 | AF6: =SUM(AA6:AE6) -> 0 | AG6: 1 | AH6: 0 | AI6: 1 | AJ6: 1 | AK6: 1 | AL6: =SUM(AG6:AK6) -> 4 | AM6: =H6+N6+T6+Z6+AF6+AL6 -> 6 | AN6: =IF(AM6=0,"Conforme",IF(AM6<=12,"Atenção","Crítico")) -> Atenção
A7: HU05 | B7: [Federal Spending] Como desenvolvedor, quero que as requisições de geração de arquivos D sejam gerenciadas e armazenadas em cache, para que requisições duplicadas não causem problemas de desempenho. | C7: 0 | D7: 0 | E7: 0 | F7: 0 | G7: 1 | H7: =SUM(C7:G7) -> 1 | I7: 1 | J7: 0 | K7: 0 | L7: 1 | M7: 0 | N7: =SUM(I7:M7) -> 2 | O7: 0 | P7: 1 | Q7: 0 | R7: 1 | S7: 0 | T7: =SUM(O7:S7) -> 2 | U7: 0 | V7: 0 | W7: 0 | X7: 0 | Y7: 0 | Z7: =SUM(U7:Y7) -> 0 | AA7: 0 | AB7: 0 | AC7: 0 | AD7: 0 | AE7: 0 | AF7: =SUM(AA7:AE7) -> 0 | AG7: 1 | AH7: 0 | AI7: 1 | AJ7: 1 | AK7: 1 | AL7: =SUM(AG7:AK7) -> 4 | AM7: =H7+N7+T7+Z7+AF7+AL7 -> 9 | AN7: =IF(AM7=0,"Conforme",IF(AM7<=12,"Atenção","Crítico")) -> Atenção
A8: HU06 | B8: [Federal Spending] Como usuário de agência, quero incluir um grande número de campos flexíveis sem impacto no desempenho. | C8: 0 | D8: 0 | E8: 0 | F8: 0 | G8: 0 | H8: =SUM(C8:G8) -> 0 | I8: 0 | J8: 0 | K8: 0 | L8: 0 | M8: 0 | N8: =SUM(I8:M8) -> 0 | O8: 0 | P8: 0 | Q8: 0 | R8: 0 | S8: 0 | T8: =SUM(O8:S8) -> 0 | U8: 1 | V8: 0 | W8: 0 | X8: 0 | Y8: 1 | Z8: =SUM(U8:Y8) -> 2 | AA8: 0 | AB8: 0 | AC8: 0 | AD8: 0 | AE8: 0 | AF8: =SUM(AA8:AE8) -> 0 | AG8: 1 | AH8: 1 | AI8: 1 | AJ8: 1 | AK8: 1 | AL8: =SUM(AG8:AK8) -> 5 | AM8: =H8+N8+T8+Z8+AF8+AL8 -> 7 | AN8: =IF(AM8=0,"Conforme",IF(AM8<=12,"Atenção","Crítico")) -> Atenção
A9: HU07 | B9: [Federal Spending] Como desenvolvedor, quero atualizar a tabela de regras de validação do Broker para contemplar as atualizações de regras do DB-2213. | C9: 1 | D9: 0 | E9: 0 | F9: 0 | G9: 0 | H9: =SUM(C9:G9) -> 1 | I9: 0 | J9: 0 | K9: 0 | L9: 0 | M9: 0 | N9: =SUM(I9:M9) -> 0 | O9: 1 | P9: 1 | Q9: 0 | R9: 1 | S9: 0 | T9: =SUM(O9:S9) -> 3 | U9: 0 | V9: 0 | W9: 0 | X9: 0 | Y9: 0 | Z9: =SUM(U9:Y9) -> 0 | AA9: 0 | AB9: 0 | AC9: 0 | AD9: 0 | AE9: 0 | AF9: =SUM(AA9:AE9) -> 0 | AG9: 1 | AH9: 0 | AI9: 1 | AJ9: 1 | AK9: 1 | AL9: =SUM(AG9:AK9) -> 4 | AM9: =H9+N9+T9+Z9+AF9+AL9 -> 8 | AN9: =IF(AM9=0,"Conforme",IF(AM9<=12,"Atenção","Crítico")) -> Atenção
A10: HU08 | B10: [Federal Spending] Como usuário do site, quero ver dados de assistência financeira atualizados diariamente. | C10: 0 | D10: 0 | E10: 0 | F10: 0 | G10: 0 | H10: =SUM(C10:G10) -> 0 | I10: 0 | J10: 0 | K10: 0 | L10: 0 | M10: 0 | N10: =SUM(I10:M10) -> 0 | O10: 1 | P10: 0 | Q10: 0 | R10: 0 | S10: 0 | T10: =SUM(O10:S10) -> 1 | U10: 0 | V10: 0 | W10: 1 | X10: 0 | Y10: 0 | Z10: =SUM(U10:Y10) -> 1 | AA10: 0 | AB10: 0 | AC10: 0 | AD10: 0 | AE10: 0 | AF10: =SUM(AA10:AE10) -> 0 | AG10: 1 | AH10: 0 | AI10: 1 | AJ10: 1 | AK10: 1 | AL10: =SUM(AG10:AK10) -> 4 | AM10: =H10+N10+T10+Z10+AF10+AL10 -> 6 | AN10: =IF(AM10=0,"Conforme",IF(AM10<=12,"Atenção","Crítico")) -> Atenção
A11: HU09 | B11: [Federal Spending] Como proprietário, quero garantir que o USAspending envie apenas registros de concessão ao meu sistema. | C11: 0 | D11: 0 | E11: 1 | F11: 0 | G11: 0 | H11: =SUM(C11:G11) -> 1 | I11: 0 | J11: 0 | K11: 0 | L11: 0 | M11: 0 | N11: =SUM(I11:M11) -> 0 | O11: 0 | P11: 0 | Q11: 0 | R11: 0 | S11: 0 | T11: =SUM(O11:S11) -> 0 | U11: 0 | V11: 0 | W11: 0 | X11: 1 | Y11: 0 | Z11: =SUM(U11:Y11) -> 1 | AA11: 0 | AB11: 0 | AC11: 0 | AD11: 0 | AE11: 0 | AF11: =SUM(AA11:AE11) -> 0 | AG11: 1 | AH11: 0 | AI11: 1 | AJ11: 1 | AK11: 1 | AL11: =SUM(AG11:AK11) -> 4 | AM11: =H11+N11+T11+Z11+AF11+AL11 -> 6 | AN11: =IF(AM11=0,"Conforme",IF(AM11<=12,"Atenção","Crítico")) -> Atenção
A12: HU10 | B12: [Federal Spending] Como usuário do broker, quero ajudar a criar mockups de conteúdo, para que eu possa enviar meus dados eficientemente. | C12: 0 | D12: 0 | E12: 0 | F12: 1 | G12: 0 | H12: =SUM(C12:G12) -> 1 | I12: 0 | J12: 0 | K12: 0 | L12: 0 | M12: 0 | N12: =SUM(I12:M12) -> 0 | O12: 0 | P12: 0 | Q12: 1 | R12: 0 | S12: 0 | T12: =SUM(O12:S12) -> 1 | U12: 0 | V12: 0 | W12: 0 | X12: 0 | Y12: 0 | Z12: =SUM(U12:Y12) -> 0 | AA12: 0 | AB12: 0 | AC12: 0 | AD12: 0 | AE12: 0 | AF12: =SUM(AA12:AE12) -> 0 | AG12: 1 | AH12: 0 | AI12: 1 | AJ12: 1 | AK12: 1 | AL12: =SUM(AG12:AK12) -> 4 | AM12: =H12+N12+T12+Z12+AF12+AL12 -> 6 | AN12: =IF(AM12=0,"Conforme",IF(AM12<=12,"Atenção","Crítico")) -> Atenção
A13: HU11 | B13: [Recycling] Como usuário, quero inserir meu CEP e obter uma lista de instalações de reciclagem próximas, para que eu possa decidir quais considerar. | C13: 0 | D13: 0 | E13: 0 | F13: 0 | G13: 0 | H13: =SUM(C13:G13) -> 0 | I13: 0 | J13: 0 | K13: 0 | L13: 0 | M13: 0 | N13: =SUM(I13:M13) -> 0 | O13: 0 | P13: 0 | Q13: 0 | R13: 0 | S13: 0 | T13: =SUM(O13:S13) -> 0 | U13: 0 | V13: 0 | W13: 0 | X13: 0 | Y13: 0 | Z13: =SUM(U13:Y13) -> 0 | AA13: 1 | AB13: 1 | AC13: 0 | AD13: 0 | AE13: 0 | AF13: =SUM(AA13:AE13) -> 2 | AG13: 1 | AH13: 0 | AI13: 1 | AJ13: 1 | AK13: 1 | AL13: =SUM(AG13:AK13) -> 4 | AM13: =H13+N13+T13+Z13+AF13+AL13 -> 6 | AN13: =IF(AM13=0,"Conforme",IF(AM13<=12,"Atenção","Crítico")) -> Atenção
A14: HU12 | B14: [Recycling] Como usuário, quero obter o horário de funcionamento de cada instalação de reciclagem, para que eu possa agendar entregas em meus dias de folga ou após o trabalho. | C14: 0 | D14: 0 | E14: 0 | F14: 0 | G14: 0 | H14: =SUM(C14:G14) -> 0 | I14: 0 | J14: 0 | K14: 0 | L14: 0 | M14: 0 | N14: =SUM(I14:M14) -> 0 | O14: 0 | P14: 0 | Q14: 0 | R14: 0 | S14: 0 | T14: =SUM(O14:S14) -> 0 | U14: 0 | V14: 0 | W14: 0 | X14: 0 | Y14: 0 | Z14: =SUM(U14:Y14) -> 0 | AA14: 0 | AB14: 0 | AC14: 0 | AD14: 0 | AE14: 0 | AF14: =SUM(AA14:AE14) -> 0 | AG14: 1 | AH14: 0 | AI14: 1 | AJ14: 1 | AK14: 1 | AL14: =SUM(AG14:AK14) -> 4 | AM14: =H14+N14+T14+Z14+AF14+AL14 -> 4 | AN14: =IF(AM14=0,"Conforme",IF(AM14<=12,"Atenção","Crítico")) -> Atenção
... A32: HU30 | B32: [Planning Poker] Como Mike, quero ver algumas métricas sobre o uso do jogo, para ver o quanto ele está sendo utilizado. | C32: 0 | D32: 0 | E32: 0 | F32: 0 | G32: 0 | H32: =SUM(C32:G32) -> 0 | I32: 0 | J32: 0 | K32: 0 | L32: 0 | M32: 0 | N32: =SUM(I32:M32) -> 0 | O32: 0 | P32: 0 | Q32: 0 | R32: 0 | S32: 1 | T32: =SUM(O32:S32) -> 1 | U32: 0 | V32: 0 | W32: 0 | X32: 0 | Y32: 0 | Z32: =SUM(U32:Y32) -> 0 | AA32: 0 | AB32: 0 | AC32: 0 | AD32: 0 | AE32: 0 | AF32: =SUM(AA32:AE32) -> 0 | AG32: 1 | AH32: 0 | AI32: 1 | AJ32: 1 | AK32: 1 | AL32: =SUM(AG32:AK32) -> 4 | AM32: =H32+N32+T32+Z32+AF32+AL32 -> 5 | AN32: =IF(AM32=0,"Conforme",IF(AM32<=12,"Atenção","Crítico")) -> Atenção

Sheet ChatGPT_FewShot
A1: Avaliação de Requirements Smells — ChatGPT FewShot
A2: HU | B2: Descrição | C2: I-1 | D2: I-2 | E2: I-3 | F2: I-4 | G2: I-5 | H2: I_Count | I2: N-1 | J2: N-2 | K2: N-3 | L2: N-4 | M2: N-5 | N2: N_Count | O2: V-1 | P2: V-2 | Q2: V-3 | R2: V-4 | S2: V-5 | T2: V_Count | U2: E-1 | V2: E-2 | W2: E-3 | X2: E-4 | Y2: E-5 | Z2: E_Count | AA2: S-1 | AB2: S-2 | AC2: S-3 | AD2: S-4 | AE2: S-5 | AF2: S_Count | AG2: T-1 | AH2: T-2 | AI2: T-3 | AJ2: T-4 | AK2: T-5 | AL2: T_Count | AM2: Total_Smells | AN2: Nível
A3: HU01 | B3: [Federal Spending] Como usuário, quero que o botão de publicar no FABS seja desativado após clicar, enquanto as derivações acontecem, para que eu não possa clicar múltiplas vezes na mesma submissão. | C3: 0 | D3: 0 | E3: 0 | F3: 0 | G3: 0 | H3: =SUM(C3:G3) -> 0 | I3: 0 | J3: 1 | K3: 0 | L3: 0 | M3: 1 | N3: =SUM(I3:M3) -> 2 | O3: 0 | P3: 0 | Q3: 0 | R3: 0 | S3: 0 | T3: =SUM(O3:S3) -> 0 | U3: 0 | V3: 0 | W3: 0 | X3: 0 | Y3: 0 | Z3: =SUM(U3:Y3) -> 0 | AA3: 0 | AB3: 0 | AC3: 0 | AD3: 0 | AE3: 0 | AF3: =SUM(AA3:AE3) -> 0 | AG3: 1 | AH3: 1 | AI3: 1 | AJ3: 0 | AK3: 0 | AL3: =SUM(AG3:AK3) -> 3 | AM3: =H3+N3+T3+Z3+AF3+AL3 -> 5 | AN3: =IF(AM3=0,"Conforme",IF(AM3<=12,"Atenção","Crítico")) -> Atenção
A4: HU02 | B4: [Federal Spending] Como usuário de agência, quero enviar meus dados com campos cercados por aspas, para que o Excel não remova zeros à esquerda ou à direita. | C4: 0 | D4: 0 | E4: 0 | F4: 0 | G4: 0 | H4: =SUM(C4:G4) -> 0 | I4: 0 | J4: 0 | K4: 1 | L4: 0 | M4: 0 | N4: =SUM(I4:M4) -> 1 | O4: 0 | P4: 0 | Q4: 0 | R4: 0 | S4: 0 | T4: =SUM(O4:S4) -> 0 | U4: 0 | V4: 0 | W4: 0 | X4: 0 | Y4: 0 | Z4: =SUM(U4:Y4) -> 0 | AA4: 0 | AB4: 0 | AC4: 0 | AD4: 0 | AE4: 0 | AF4: =SUM(AA4:AE4) -> 0 | AG4: 1 | AH4: 0 | AI4: 1 | AJ4: 0 | AK4: 0 | AL4: =SUM(AG4:AK4) -> 2 | AM4: =H4+N4+T4+Z4+AF4+AL4 -> 3 | AN4: =IF(AM4=0,"Conforme",IF(AM4<=12,"Atenção","Crítico")) -> Atenção
A5: HU03 | B5: [Federal Spending] Como usuário do site, quero acessar os arquivos publicados pelo FABS, para que eu possa ver os novos arquivos conforme chegam. | C5: 0 | D5: 0 | E5: 0 | F5: 0 | G5: 0 | H5: =SUM(C5:G5) -> 0 | I5: 0 | J5: 0 | K5: 0 | L5: 0 | M5: 0 | N5: =SUM(I5:M5) -> 0 | O5: 0 | P5: 0 | Q5: 0 | R5: 0 | S5: 0 | T5: =SUM(O5:S5) -> 0 | U5: 0 | V5: 0 | W5: 0 | X5: 0 | Y5: 0 | Z5: =SUM(U5:Y5) -> 0 | AA5: 0 | AB5: 0 | AC5: 0 | AD5: 0 | AE5: 0 | AF5: =SUM(AA5:AE5) -> 0 | AG5: 1 | AH5: 0 | AI5: 0 | AJ5: 0 | AK5: 0 | AL5: =SUM(AG5:AK5) -> 1 | AM5: =H5+N5+T5+Z5+AF5+AL5 -> 1 | AN5: =IF(AM5=0,"Conforme",IF(AM5<=12,"Atenção","Crítico")) -> Atenção
A6: HU04 | B6: [Federal Spending] Como usuário da agência, quero receber um erro de arquivo mais útil ao enviar um arquivo com extensão incorreta. | C6: 0 | D6: 0 | E6: 0 | F6: 0 | G6: 0 | H6: =SUM(C6:G6) -> 0 | I6: 0 | J6: 0 | K6: 0 | L6: 0 | M6: 0 | N6: =SUM(I6:M6) -> 0 | O6: 1 | P6: 0 | Q6: 0 | R6: 0 | S6: 0 | T6: =SUM(O6:S6) -> 1 | U6: 0 | V6: 0 | W6: 0 | X6: 0 | Y6: 0 | Z6: =SUM(U6:Y6) -> 0 | AA6: 0 | AB6: 0 | AC6: 0 | AD6: 0 | AE6: 0 | AF6: =SUM(AA6:AE6) -> 0 | AG6: 1 | AH6: 0 | AI6: 0 | AJ6: 0 | AK6: 0 | AL6: =SUM(AG6:AK6) -> 1 | AM6: =H6+N6+T6+Z6+AF6+AL6 -> 2 | AN6: =IF(AM6=0,"Conforme",IF(AM6<=12,"Atenção","Crítico")) -> Atenção
A7: HU05 | B7: [Federal Spending] Como desenvolvedor, quero que as requisições de geração de arquivos D sejam gerenciadas e armazenadas em cache, para que requisições duplicadas não causem problemas de desempenho. | C7: 0 | D7: 0 | E7: 0 | F7: 0 | G7: 0 | H7: =SUM(C7:G7) -> 0 | I7: 0 | J7: 0 | K7: 0 | L7: 1 | M7: 0 | N7: =SUM(I7:M7) -> 1 | O7: 0 | P7: 0 | Q7: 0 | R7: 0 | S7: 0 | T7: =SUM(O7:S7) -> 0 | U7: 0 | V7: 0 | W7: 0 | X7: 0 | Y7: 0 | Z7: =SUM(U7:Y7) -> 0 | AA7: 0 | AB7: 0 | AC7: 0 | AD7: 0 | AE7: 0 | AF7: =SUM(AA7:AE7) -> 0 | AG7: 1 | AH7: 0 | AI7: 0 | AJ7: 0 | AK7: 0 | AL7: =SUM(AG7:AK7) -> 1 | AM7: =H7+N7+T7+Z7+AF7+AL7 -> 2 | AN7: =IF(AM7=0,"Conforme",IF(AM7<=12,"Atenção","Crítico")) -> Atenção
A8: HU06 | B8: [Federal Spending] Como usuário de agência, quero incluir um grande número de campos flexíveis sem impacto no desempenho. | C8: 0 | D8: 0 | E8: 0 | F8: 0 | G8: 0 | H8: =SUM(C8:G8) -> 0 | I8: 0 | J8: 0 | K8: 0 | L8: 0 | M8: 0 | N8: =SUM(I8:M8) -> 0 | O8: 0 | P8: 0 | Q8: 0 | R8: 0 | S8: 0 | T8: =SUM(O8:S8) -> 0 | U8: 1 | V8: 0 | W8: 0 | X8: 0 | Y8: 1 | Z8: =SUM(U8:Y8) -> 2 | AA8: 0 | AB8: 0 | AC8: 0 | AD8: 0 | AE8: 0 | AF8: =SUM(AA8:AE8) -> 0 | AG8: 1 | AH8: 1 | AI8: 0 | AJ8: 0 | AK8: 0 | AL8: =SUM(AG8:AK8) -> 2 | AM8: =H8+N8+T8+Z8+AF8+AL8 -> 4 | AN8: =IF(AM8=0,"Conforme",IF(AM8<=12,"Atenção","Crítico")) -> Atenção
A9: HU07 | B9: [Federal Spending] Como desenvolvedor, quero atualizar a tabela de regras de validação do Broker para contemplar as atualizações de regras do DB-2213. | C9: 1 | D9: 0 | E9: 0 | F9: 0 | G9: 0 | H9: =SUM(C9:G9) -> 1 | I9: 0 | J9: 0 | K9: 0 | L9: 0 | M9: 0 | N9: =SUM(I9:M9) -> 0 | O9: 0 | P9: 0 | Q9: 0 | R9: 0 | S9: 0 | T9: =SUM(O9:S9) -> 0 | U9: 0 | V9: 0 | W9: 0 | X9: 0 | Y9: 0 | Z9: =SUM(U9:Y9) -> 0 | AA9: 0 | AB9: 0 | AC9: 0 | AD9: 0 | AE9: 0 | AF9: =SUM(AA9:AE9) -> 0 | AG9: 1 | AH9: 0 | AI9: 0 | AJ9: 0 | AK9: 0 | AL9: =SUM(AG9:AK9) -> 1 | AM9: =H9+N9+T9+Z9+AF9+AL9 -> 2 | AN9: =IF(AM9=0,"Conforme",IF(AM9<=12,"Atenção","Crítico")) -> Atenção
A10: HU08 | B10: [Federal Spending] Como usuário do site, quero ver dados de assistência financeira atualizados diariamente. | C10: 0 | D10: 0 | E10: 0 | F10: 0 | G10: 0 | H10: =SUM(C10:G10) -> 0 | I10: 0 | J10: 0 | K10: 0 | L10: 0 | M10: 0 | N10: =SUM(I10:M10) -> 0 | O10: 0 | P10: 0 | Q10: 0 | R10: 0 | S10: 0 | T10: =SUM(O10:S10) -> 0 | U10: 0 | V10: 0 | W10: 1 | X10: 0 | Y10: 0 | Z10: =SUM(U10:Y10) -> 1 | AA10: 0 | AB10: 0 | AC10: 0 | AD10: 0 | AE10: 0 | AF10: =SUM(AA10:AE10) -> 0 | AG10: 1 | AH10: 0 | AI10: 0 | AJ10: 0 | AK10: 0 | AL10: =SUM(AG10:AK10) -> 1 | AM10: =H10+N10+T10+Z10+AF10+AL10 -> 2 | AN10: =IF(AM10=0,"Conforme",IF(AM10<=12,"Atenção","Crítico")) -> Atenção
A11: HU09 | B11: [Federal Spending] Como proprietário, quero garantir que o USAspending envie apenas registros de concessão ao meu sistema. | C11: 0 | D11: 0 | E11: 0 | F11: 0 | G11: 0 | H11: =SUM(C11:G11) -> 0 | I11: 0 | J11: 0 | K11: 0 | L11: 0 | M11: 0 | N11: =SUM(I11:M11) -> 0 | O11: 0 | P11: 0 | Q11: 0 | R11: 0 | S11: 0 | T11: =SUM(O11:S11) -> 0 | U11: 0 | V11: 0 | W11: 0 | X11: 1 | Y11: 0 | Z11: =SUM(U11:Y11) -> 1 | AA11: 0 | AB11: 0 | AC11: 0 | AD11: 0 | AE11: 0 | AF11: =SUM(AA11:AE11) -> 0 | AG11: 1 | AH11: 0 | AI11: 0 | AJ11: 0 | AK11: 0 | AL11: =SUM(AG11:AK11) -> 1 | AM11: =H11+N11+T11+Z11+AF11+AL11 -> 2 | AN11: =IF(AM11=0,"Conforme",IF(AM11<=12,"Atenção","Crítico")) -> Atenção
A12: HU10 | B12: [Federal Spending] Como usuário do broker, quero ajudar a criar mockups de conteúdo, para que eu possa enviar meus dados eficientemente. | C12: 0 | D12: 0 | E12: 0 | F12: 0 | G12: 0 | H12: =SUM(C12:G12) -> 0 | I12: 0 | J12: 0 | K12: 0 | L12: 0 | M12: 0 | N12: =SUM(I12:M12) -> 0 | O12: 0 | P12: 0 | Q12: 0 | R12: 0 | S12: 0 | T12: =SUM(O12:S12) -> 0 | U12: 0 | V12: 0 | W12: 0 | X12: 0 | Y12: 0 | Z12: =SUM(U12:Y12) -> 0 | AA12: 0 | AB12: 0 | AC12: 0 | AD12: 0 | AE12: 0 | AF12: =SUM(AA12:AE12) -> 0 | AG12: 1 | AH12: 0 | AI12: 0 | AJ12: 0 | AK12: 0 | AL12: =SUM(AG12:AK12) -> 1 | AM12: =H12+N12+T12+Z12+AF12+AL12 -> 1 | AN12: =IF(AM12=0,"Conforme",IF(AM12<=12,"Atenção","Crítico")) -> Atenção
A13: HU11 | B13: [Recycling] Como usuário, quero inserir meu CEP e obter uma lista de instalações de reciclagem próximas, para que eu possa decidir quais considerar. | C13: 0 | D13: 0 | E13: 0 | F13: 0 | G13: 0 | H13: =SUM(C13:G13) -> 0 | I13: 0 | J13: 0 | K13: 0 | L13: 0 | M13: 0 | N13: =SUM(I13:M13) -> 0 | O13: 0 | P13: 0 | Q13: 0 | R13: 0 | S13: 0 | T13: =SUM(O13:S13) -> 0 | U13: 0 | V13: 0 | W13: 0 | X13: 0 | Y13: 0 | Z13: =SUM(U13:Y13) -> 0 | AA13: 0 | AB13: 0 | AC13: 0 | AD13: 0 | AE13: 0 | AF13: =SUM(AA13:AE13) -> 0 | AG13: 1 | AH13: 0 | AI13: 0 | AJ13: 0 | AK13: 0 | AL13: =SUM(AG13:AK13) -> 1 | AM13: =H13+N13+T13+Z13+AF13+AL13 -> 1 | AN13: =IF(AM13=0,"Conforme",IF(AM13<=12,"Atenção","Crítico")) -> Atenção
A14: HU12 | B14: [Recycling] Como usuário, quero obter o horário de funcionamento de cada instalação de reciclagem, para que eu possa agendar entregas em meus dias de folga ou após o trabalho. | C14: 0 | D14: 0 | E14: 0 | F14: 0 | G14: 0 | H14: =SUM(C14:G14) -> 0 | I14: 0 | J14: 0 | K14: 0 | L14: 0 | M14: 0 | N14: =SUM(I14:M14) -> 0 | O14: 0 | P14: 0 | Q14: 0 | R14: 0 | S14: 0 | T14: =SUM(O14:S14) -> 0 | U14: 0 | V14: 0 | W14: 0 | X14: 0 | Y14: 0 | Z14: =SUM(U14:Y14) -> 0 | AA14: 0 | AB14: 0 | AC14: 0 | AD14: 0 | AE14: 0 | AF14: =SUM(AA14:AE14) -> 0 | AG14: 1 | AH14: 0 | AI14: 0 | AJ14: 0 | AK14: 0 | AL14: =SUM(AG14:AK14) -> 1 | AM14: =H14+N14+T14+Z14+AF14+AL14 -> 1 | AN14: =IF(AM14=0,"Conforme",IF(AM14<=12,"Atenção","Crítico")) -> Atenção
... A32: HU30 | B32: [Planning Poker] Como Mike, quero ver algumas métricas sobre o uso do jogo, para ver o quanto ele está sendo utilizado. | C32: 0 | D32: 0 | E32: 0 | F32: 0 | G32: 0 | H32: =SUM(C32:G32) -> 0 | I32: 0 | J32: 0 | K32: 0 | L32: 0 | M32: 0 | N32: =SUM(I32:M32) -> 0 | O32: 0 | P32: 0 | Q32: 0 | R32: 0 | S32: 1 | T32: =SUM(O32:S32) -> 1 | U32: 0 | V32: 0 | W32: 0 | X32: 0 | Y32: 0 | Z32: =SUM(U32:Y32) -> 0 | AA32: 0 | AB32: 0 | AC32: 0 | AD32: 0 | AE32: 0 | AF32: =SUM(AA32:AE32) -> 0 | AG32: 1 | AH32: 0 | AI32: 0 | AJ32: 0 | AK32: 0 | AL32: =SUM(AG32:AK32) -> 1 | AM32: =H32+N32+T32+Z32+AF32+AL32 -> 2 | AN32: =IF(AM32=0,"Conforme",IF(AM32<=12,"Atenção","Crítico")) -> Atenção

Sheet ChatGPT_CoT
A1: Avaliação de Requirements Smells — ChatGPT CoT
A2: HU | B2: Descrição | C2: I-1 | D2: I-2 | E2: I-3 | F2: I-4 | G2: I-5 | H2: I_Count | I2: N-1 | J2: N-2 | K2: N-3 | L2: N-4 | M2: N-5 | N2: N_Count | O2: V-1 | P2: V-2 | Q2: V-3 | R2: V-4 | S2: V-5 | T2: V_Count | U2: E-1 | V2: E-2 | W2: E-3 | X2: E-4 | Y2: E-5 | Z2: E_Count | AA2: S-1 | AB2: S-2 | AC2: S-3 | AD2: S-4 | AE2: S-5 | AF2: S_Count | AG2: T-1 | AH2: T-2 | AI2: T-3 | AJ2: T-4 | AK2: T-5 | AL2: T_Count | AM2: Total_Smells | AN2: Nível
A3: HU01 | B3: [Federal Spending] Como usuário, quero que o botão de publicar no FABS seja desativado após clicar, enquanto as derivações acontecem, para que eu não possa clicar múltiplas vezes na mesma submissão. | C3: 0 | D3: 0 | E3: 1 | F3: 0 | G3: 0 | H3: =SUM(C3:G3) -> 1 | I3: 0 | J3: 1 | K3: 0 | L3: 0 | M3: 0 | N3: =SUM(I3:M3) -> 1 | O3: 0 | P3: 0 | Q3: 0 | R3: 0 | S3: 0 | T3: =SUM(O3:S3) -> 0 | U3: 0 | V3: 0 | W3: 0 | X3: 0 | Y3: 0 | Z3: =SUM(U3:Y3) -> 0 | AA3: 0 | AB3: 0 | AC3: 0 | AD3: 0 | AE3: 0 | AF3: =SUM(AA3:AE3) -> 0 | AG3: 1 | AH3: 0 | AI3: 1 | AJ3: 1 | AK3: 1 | AL3: =SUM(AG3:AK3) -> 4 | AM3: =H3+N3+T3+Z3+AF3+AL3 -> 6 | AN3: =IF(AM3=0,"Conforme",IF(AM3<=12,"Atenção","Crítico")) -> Atenção
A4: HU02 | B4: [Federal Spending] Como usuário de agência, quero enviar meus dados com campos cercados por aspas, para que o Excel não remova zeros à esquerda ou à direita. | C4: 0 | D4: 0 | E4: 0 | F4: 0 | G4: 0 | H4: =SUM(C4:G4) -> 0 | I4: 0 | J4: 0 | K4: 1 | L4: 0 | M4: 0 | N4: =SUM(I4:M4) -> 1 | O4: 0 | P4: 0 | Q4: 0 | R4: 0 | S4: 0 | T4: =SUM(O4:S4) -> 0 | U4: 0 | V4: 0 | W4: 0 | X4: 0 | Y4: 0 | Z4: =SUM(U4:Y4) -> 0 | AA4: 0 | AB4: 0 | AC4: 0 | AD4: 0 | AE4: 0 | AF4: =SUM(AA4:AE4) -> 0 | AG4: 1 | AH4: 0 | AI4: 1 | AJ4: 1 | AK4: 1 | AL4: =SUM(AG4:AK4) -> 4 | AM4: =H4+N4+T4+Z4+AF4+AL4 -> 5 | AN4: =IF(AM4=0,"Conforme",IF(AM4<=12,"Atenção","Crítico")) -> Atenção
A5: HU03 | B5: [Federal Spending] Como usuário do site, quero acessar os arquivos publicados pelo FABS, para que eu possa ver os novos arquivos conforme chegam. | C5: 0 | D5: 0 | E5: 1 | F5: 0 | G5: 0 | H5: =SUM(C5:G5) -> 1 | I5: 0 | J5: 0 | K5: 0 | L5: 0 | M5: 0 | N5: =SUM(I5:M5) -> 0 | O5: 0 | P5: 0 | Q5: 0 | R5: 0 | S5: 0 | T5: =SUM(O5:S5) -> 0 | U5: 0 | V5: 0 | W5: 1 | X5: 0 | Y5: 0 | Z5: =SUM(U5:Y5) -> 1 | AA5: 0 | AB5: 0 | AC5: 0 | AD5: 0 | AE5: 0 | AF5: =SUM(AA5:AE5) -> 0 | AG5: 1 | AH5: 0 | AI5: 1 | AJ5: 1 | AK5: 1 | AL5: =SUM(AG5:AK5) -> 4 | AM5: =H5+N5+T5+Z5+AF5+AL5 -> 6 | AN5: =IF(AM5=0,"Conforme",IF(AM5<=12,"Atenção","Crítico")) -> Atenção
A6: HU04 | B6: [Federal Spending] Como usuário da agência, quero receber um erro de arquivo mais útil ao enviar um arquivo com extensão incorreta. | C6: 0 | D6: 0 | E6: 0 | F6: 0 | G6: 0 | H6: =SUM(C6:G6) -> 0 | I6: 0 | J6: 0 | K6: 0 | L6: 0 | M6: 0 | N6: =SUM(I6:M6) -> 0 | O6: 1 | P6: 0 | Q6: 0 | R6: 0 | S6: 0 | T6: =SUM(O6:S6) -> 1 | U6: 1 | V6: 0 | W6: 0 | X6: 0 | Y6: 0 | Z6: =SUM(U6:Y6) -> 1 | AA6: 0 | AB6: 0 | AC6: 0 | AD6: 0 | AE6: 0 | AF6: =SUM(AA6:AE6) -> 0 | AG6: 1 | AH6: 0 | AI6: 1 | AJ6: 1 | AK6: 1 | AL6: =SUM(AG6:AK6) -> 4 | AM6: =H6+N6+T6+Z6+AF6+AL6 -> 6 | AN6: =IF(AM6=0,"Conforme",IF(AM6<=12,"Atenção","Crítico")) -> Atenção
A7: HU05 | B7: [Federal Spending] Como desenvolvedor, quero que as requisições de geração de arquivos D sejam gerenciadas e armazenadas em cache, para que requisições duplicadas não causem problemas de desempenho. | C7: 0 | D7: 0 | E7: 0 | F7: 0 | G7: 1 | H7: =SUM(C7:G7) -> 1 | I7: 0 | J7: 0 | K7: 0 | L7: 1 | M7: 0 | N7: =SUM(I7:M7) -> 1 | O7: 0 | P7: 1 | Q7: 0 | R7: 0 | S7: 0 | T7: =SUM(O7:S7) -> 1 | U7: 0 | V7: 0 | W7: 0 | X7: 0 | Y7: 0 | Z7: =SUM(U7:Y7) -> 0 | AA7: 0 | AB7: 0 | AC7: 0 | AD7: 0 | AE7: 0 | AF7: =SUM(AA7:AE7) -> 0 | AG7: 1 | AH7: 0 | AI7: 1 | AJ7: 1 | AK7: 1 | AL7: =SUM(AG7:AK7) -> 4 | AM7: =H7+N7+T7+Z7+AF7+AL7 -> 7 | AN7: =IF(AM7=0,"Conforme",IF(AM7<=12,"Atenção","Crítico")) -> Atenção
A8: HU06 | B8: [Federal Spending] Como usuário de agência, quero incluir um grande número de campos flexíveis sem impacto no desempenho. | C8: 0 | D8: 0 | E8: 0 | F8: 0 | G8: 0 | H8: =SUM(C8:G8) -> 0 | I8: 0 | J8: 0 | K8: 0 | L8: 0 | M8: 0 | N8: =SUM(I8:M8) -> 0 | O8: 1 | P8: 0 | Q8: 0 | R8: 0 | S8: 0 | T8: =SUM(O8:S8) -> 1 | U8: 1 | V8: 0 | W8: 0 | X8: 0 | Y8: 1 | Z8: =SUM(U8:Y8) -> 2 | AA8: 0 | AB8: 0 | AC8: 0 | AD8: 0 | AE8: 0 | AF8: =SUM(AA8:AE8) -> 0 | AG8: 1 | AH8: 1 | AI8: 1 | AJ8: 1 | AK8: 1 | AL8: =SUM(AG8:AK8) -> 5 | AM8: =H8+N8+T8+Z8+AF8+AL8 -> 8 | AN8: =IF(AM8=0,"Conforme",IF(AM8<=12,"Atenção","Crítico")) -> Atenção
A9: HU07 | B9: [Federal Spending] Como desenvolvedor, quero atualizar a tabela de regras de validação do Broker para contemplar as atualizações de regras do DB-2213. | C9: 1 | D9: 0 | E9: 0 | F9: 0 | G9: 0 | H9: =SUM(C9:G9) -> 1 | I9: 0 | J9: 0 | K9: 0 | L9: 0 | M9: 0 | N9: =SUM(I9:M9) -> 0 | O9: 1 | P9: 1 | Q9: 0 | R9: 0 | S9: 0 | T9: =SUM(O9:S9) -> 2 | U9: 0 | V9: 0 | W9: 0 | X9: 0 | Y9: 0 | Z9: =SUM(U9:Y9) -> 0 | AA9: 0 | AB9: 0 | AC9: 0 | AD9: 0 | AE9: 0 | AF9: =SUM(AA9:AE9) -> 0 | AG9: 1 | AH9: 0 | AI9: 1 | AJ9: 1 | AK9: 1 | AL9: =SUM(AG9:AK9) -> 4 | AM9: =H9+N9+T9+Z9+AF9+AL9 -> 7 | AN9: =IF(AM9=0,"Conforme",IF(AM9<=12,"Atenção","Crítico")) -> Atenção
A10: HU08 | B10: [Federal Spending] Como usuário do site, quero ver dados de assistência financeira atualizados diariamente. | C10: 0 | D10: 0 | E10: 0 | F10: 0 | G10: 0 | H10: =SUM(C10:G10) -> 0 | I10: 0 | J10: 0 | K10: 0 | L10: 0 | M10: 0 | N10: =SUM(I10:M10) -> 0 | O10: 1 | P10: 0 | Q10: 0 | R10: 0 | S10: 0 | T10: =SUM(O10:S10) -> 1 | U10: 0 | V10: 0 | W10: 1 | X10: 0 | Y10: 0 | Z10: =SUM(U10:Y10) -> 1 | AA10: 0 | AB10: 0 | AC10: 0 | AD10: 0 | AE10: 0 | AF10: =SUM(AA10:AE10) -> 0 | AG10: 1 | AH10: 0 | AI10: 1 | AJ10: 1 | AK10: 1 | AL10: =SUM(AG10:AK10) -> 4 | AM10: =H10+N10+T10+Z10+AF10+AL10 -> 6 | AN10: =IF(AM10=0,"Conforme",IF(AM10<=12,"Atenção","Crítico")) -> Atenção
A11: HU09 | B11: [Federal Spending] Como proprietário, quero garantir que o USAspending envie apenas registros de concessão ao meu sistema. | C11: 0 | D11: 0 | E11: 1 | F11: 0 | G11: 0 | H11: =SUM(C11:G11) -> 1 | I11: 0 | J11: 0 | K11: 0 | L11: 0 | M11: 0 | N11: =SUM(I11:M11) -> 0 | O11: 0 | P11: 0 | Q11: 0 | R11: 0 | S11: 0 | T11: =SUM(O11:S11) -> 0 | U11: 0 | V11: 0 | W11: 0 | X11: 1 | Y11: 0 | Z11: =SUM(U11:Y11) -> 1 | AA11: 0 | AB11: 0 | AC11: 0 | AD11: 0 | AE11: 0 | AF11: =SUM(AA11:AE11) -> 0 | AG11: 1 | AH11: 0 | AI11: 1 | AJ11: 1 | AK11: 1 | AL11: =SUM(AG11:AK11) -> 4 | AM11: =H11+N11+T11+Z11+AF11+AL11 -> 6 | AN11: =IF(AM11=0,"Conforme",IF(AM11<=12,"Atenção","Crítico")) -> Atenção
A12: HU10 | B12: [Federal Spending] Como usuário do broker, quero ajudar a criar mockups de conteúdo, para que eu possa enviar meus dados eficientemente. | C12: 0 | D12: 0 | E12: 0 | F12: 1 | G12: 0 | H12: =SUM(C12:G12) -> 1 | I12: 0 | J12: 0 | K12: 0 | L12: 0 | M12: 0 | N12: =SUM(I12:M12) -> 0 | O12: 0 | P12: 0 | Q12: 0 | R12: 0 | S12: 0 | T12: =SUM(O12:S12) -> 0 | U12: 0 | V12: 0 | W12: 0 | X12: 0 | Y12: 0 | Z12: =SUM(U12:Y12) -> 0 | AA12: 0 | AB12: 0 | AC12: 0 | AD12: 0 | AE12: 0 | AF12: =SUM(AA12:AE12) -> 0 | AG12: 1 | AH12: 0 | AI12: 1 | AJ12: 1 | AK12: 1 | AL12: =SUM(AG12:AK12) -> 4 | AM12: =H12+N12+T12+Z12+AF12+AL12 -> 5 | AN12: =IF(AM12=0,"Conforme",IF(AM12<=12,"Atenção","Crítico")) -> Atenção
A13: HU11 | B13: [Recycling] Como usuário, quero inserir meu CEP e obter uma lista de instalações de reciclagem próximas, para que eu possa decidir quais considerar. | C13: 0 | D13: 0 | E13: 0 | F13: 0 | G13: 0 | H13: =SUM(C13:G13) -> 0 | I13: 0 | J13: 0 | K13: 0 | L13: 0 | M13: 0 | N13: =SUM(I13:M13) -> 0 | O13: 0 | P13: 0 | Q13: 0 | R13: 0 | S13: 0 | T13: =SUM(O13:S13) -> 0 | U13: 0 | V13: 0 | W13: 0 | X13: 0 | Y13: 0 | Z13: =SUM(U13:Y13) -> 0 | AA13: 1 | AB13: 0 | AC13: 0 | AD13: 0 | AE13: 0 | AF13: =SUM(AA13:AE13) -> 1 | AG13: 1 | AH13: 0 | AI13: 1 | AJ13: 1 | AK13: 1 | AL13: =SUM(AG13:AK13) -> 4 | AM13: =H13+N13+T13+Z13+AF13+AL13 -> 5 | AN13: =IF(AM13=0,"Conforme",IF(AM13<=12,"Atenção","Crítico")) -> Atenção
A14: HU12 | B14: [Recycling] Como usuário, quero obter o horário de funcionamento de cada instalação de reciclagem, para que eu possa agendar entregas em meus dias de folga ou após o trabalho. | C14: 0 | D14: 0 | E14: 0 | F14: 0 | G14: 0 | H14: =SUM(C14:G14) -> 0 | I14: 0 | J14: 0 | K14: 0 | L14: 0 | M14: 0 | N14: =SUM(I14:M14) -> 0 | O14: 0 | P14: 0 | Q14: 0 | R14: 0 | S14: 0 | T14: =SUM(O14:S14) -> 0 | U14: 0 | V14: 0 | W14: 0 | X14: 0 | Y14: 0 | Z14: =SUM(U14:Y14) -> 0 | AA14: 0 | AB14: 0 | AC14: 0 | AD14: 0 | AE14: 0 | AF14: =SUM(AA14:AE14) -> 0 | AG14: 1 | AH14: 0 | AI14: 1 | AJ14: 1 | AK14: 1 | AL14: =SUM(AG14:AK14) -> 4 | AM14: =H14+N14+T14+Z14+AF14+AL14 -> 4 | AN14: =IF(AM14=0,"Conforme",IF(AM14<=12,"Atenção","Crítico")) -> Atenção
... A32: HU30 | B32: [Planning Poker] Como Mike, quero ver algumas métricas sobre o uso do jogo, para ver o quanto ele está sendo utilizado. | C32: 0 | D32: 0 | E32: 0 | F32: 0 | G32: 0 | H32: =SUM(C32:G32) -> 0 | I32: 0 | J32: 0 | K32: 0 | L32: 0 | M32: 0 | N32: =SUM(I32:M32) -> 0 | O32: 0 | P32: 0 | Q32: 0 | R32: 0 | S32: 1 | T32: =SUM(O32:S32) -> 1 | U32: 0 | V32: 0 | W32: 0 | X32: 0 | Y32: 0 | Z32: =SUM(U32:Y32) -> 0 | AA32: 0 | AB32: 0 | AC32: 0 | AD32: 0 | AE32: 0 | AF32: =SUM(AA32:AE32) -> 0 | AG32: 1 | AH32: 0 | AI32: 1 | AJ32: 1 | AK32: 1 | AL32: =SUM(AG32:AK32) -> 4 | AM32: =H32+N32+T32+Z32+AF32+AL32 -> 5 | AN32: =IF(AM32=0,"Conforme",IF(AM32<=12,"Atenção","Crítico")) -> Atenção

Sheet Gemini_ZeroShot
A1: Avaliação de Requirements Smells — Gemini ZeroShot
A2: HU | B2: Descrição | C2: I-1 | D2: I-2 | E2: I-3 | F2: I-4 | G2: I-5 | H2: I_Count | I2: N-1 | J2: N-2 | K2: N-3 | L2: N-4 | M2: N-5 | N2: N_Count | O2: V-1 | P2: V-2 | Q2: V-3 | R2: V-4 | S2: V-5 | T2: V_Count | U2: E-1 | V2: E-2 | W2: E-3 | X2: E-4 | Y2: E-5 | Z2: E_Count | AA2: S-1 | AB2: S-2 | AC2: S-3 | AD2: S-4 | AE2: S-5 | AF2: S_Count | AG2: T-1 | AH2: T-2 | AI2: T-3 | AJ2: T-4 | AK2: T-5 | AL2: T_Count | AM2: Total_Smells | AN2: Nível
A3: HU01 | B3: [Federal Spending] Como usuário, quero que o botão de publicar no FABS seja desativado após clicar, enquanto as derivações acontecem, para que eu não possa clicar múltiplas vezes na mesma submissão. | C3: 0 | D3: 0 | E3: 0 | F3: 0 | G3: 0 | H3: =SUM(C3:G3) -> 0 | I3: 0 | J3: 0 | K3: 0 | L3: 0 | M3: 0 | N3: =SUM(I3:M3) -> 0 | O3: 0 | P3: 0 | Q3: 0 | R3: 0 | S3: 0 | T3: =SUM(O3:S3) -> 0 | U3: 0 | V3: 0 | W3: 0 | X3: 0 | Y3: 0 | Z3: =SUM(U3:Y3) -> 0 | AA3: 0 | AB3: 0 | AC3: 0 | AD3: 0 | AE3: 0 | AF3: =SUM(AA3:AE3) -> 0 | AG3: 0 | AH3: 0 | AI3: 0 | AJ3: 0 | AK3: 0 | AL3: =SUM(AG3:AK3) -> 0 | AM3: =H3+N3+T3+Z3+AF3+AL3 -> 0 | AN3: =IF(AM3=0,"Conforme",IF(AM3<=12,"Atenção","Crítico")) -> Conforme
A4: HU02 | B4: [Federal Spending] Como usuário de agência, quero enviar meus dados com campos cercados por aspas, para que o Excel não remova zeros à esquerda ou à direita. | C4: 0 | D4: 0 | E4: 0 | F4: 0 | G4: 0 | H4: =SUM(C4:G4) -> 0 | I4: 0 | J4: 0 | K4: 1 | L4: 0 | M4: 0 | N4: =SUM(I4:M4) -> 1 | O4: 0 | P4: 0 | Q4: 0 | R4: 0 | S4: 0 | T4: =SUM(O4:S4) -> 0 | U4: 0 | V4: 0 | W4: 0 | X4: 0 | Y4: 0 | Z4: =SUM(U4:Y4) -> 0 | AA4: 0 | AB4: 0 | AC4: 0 | AD4: 0 | AE4: 0 | AF4: =SUM(AA4:AE4) -> 0 | AG4: 0 | AH4: 0 | AI4: 0 | AJ4: 0 | AK4: 0 | AL4: =SUM(AG4:AK4) -> 0 | AM4: =H4+N4+T4+Z4+AF4+AL4 -> 1 | AN4: =IF(AM4=0,"Conforme",IF(AM4<=12,"Atenção","Crítico")) -> Atenção
A5: HU03 | B5: [Federal Spending] Como usuário do site, quero acessar os arquivos publicados pelo FABS, para que eu possa ver os novos arquivos conforme chegam. | C5: 0 | D5: 0 | E5: 0 | F5: 0 | G5: 0 | H5: =SUM(C5:G5) -> 0 | I5: 0 | J5: 0 | K5: 0 | L5: 0 | M5: 0 | N5: =SUM(I5:M5) -> 0 | O5: 0 | P5: 0 | Q5: 0 | R5: 0 | S5: 0 | T5: =SUM(O5:S5) -> 0 | U5: 0 | V5: 0 | W5: 0 | X5: 0 | Y5: 0 | Z5: =SUM(U5:Y5) -> 0 | AA5: 0 | AB5: 0 | AC5: 0 | AD5: 0 | AE5: 0 | AF5: =SUM(AA5:AE5) -> 0 | AG5: 0 | AH5: 0 | AI5: 0 | AJ5: 0 | AK5: 0 | AL5: =SUM(AG5:AK5) -> 0 | AM5: =H5+N5+T5+Z5+AF5+AL5 -> 0 | AN5: =IF(AM5=0,"Conforme",IF(AM5<=12,"Atenção","Crítico")) -> Conforme
A6: HU04 | B6: [Federal Spending] Como usuário da agência, quero receber um erro de arquivo mais útil ao enviar um arquivo com extensão incorreta. | C6: 0 | D6: 0 | E6: 0 | F6: 0 | G6: 0 | H6: =SUM(C6:G6) -> 0 | I6: 0 | J6: 0 | K6: 0 | L6: 0 | M6: 0 | N6: =SUM(I6:M6) -> 0 | O6: 1 | P6: 0 | Q6: 0 | R6: 0 | S6: 0 | T6: =SUM(O6:S6) -> 1 | U6: 0 | V6: 0 | W6: 0 | X6: 0 | Y6: 0 | Z6: =SUM(U6:Y6) -> 0 | AA6: 0 | AB6: 0 | AC6: 0 | AD6: 0 | AE6: 0 | AF6: =SUM(AA6:AE6) -> 0 | AG6: 0 | AH6: 0 | AI6: 0 | AJ6: 0 | AK6: 0 | AL6: =SUM(AG6:AK6) -> 0 | AM6: =H6+N6+T6+Z6+AF6+AL6 -> 1 | AN6: =IF(AM6=0,"Conforme",IF(AM6<=12,"Atenção","Crítico")) -> Atenção
A7: HU05 | B7: [Federal Spending] Como desenvolvedor, quero que as requisições de geração de arquivos D sejam gerenciadas e armazenadas em cache, para que requisições duplicadas não causem problemas de desempenho. | C7: 0 | D7: 0 | E7: 0 | F7: 0 | G7: 1 | H7: =SUM(C7:G7) -> 1 | I7: 0 | J7: 0 | K7: 0 | L7: 1 | M7: 0 | N7: =SUM(I7:M7) -> 1 | O7: 0 | P7: 0 | Q7: 0 | R7: 0 | S7: 0 | T7: =SUM(O7:S7) -> 0 | U7: 0 | V7: 0 | W7: 0 | X7: 0 | Y7: 0 | Z7: =SUM(U7:Y7) -> 0 | AA7: 0 | AB7: 0 | AC7: 0 | AD7: 0 | AE7: 0 | AF7: =SUM(AA7:AE7) -> 0 | AG7: 0 | AH7: 0 | AI7: 0 | AJ7: 0 | AK7: 0 | AL7: =SUM(AG7:AK7) -> 0 | AM7: =H7+N7+T7+Z7+AF7+AL7 -> 2 | AN7: =IF(AM7=0,"Conforme",IF(AM7<=12,"Atenção","Crítico")) -> Atenção
A8: HU06 | B8: [Federal Spending] Como usuário de agência, quero incluir um grande número de campos flexíveis sem impacto no desempenho. | C8: 0 | D8: 0 | E8: 0 | F8: 0 | G8: 0 | H8: =SUM(C8:G8) -> 0 | I8: 0 | J8: 0 | K8: 0 | L8: 0 | M8: 0 | N8: =SUM(I8:M8) -> 0 | O8: 0 | P8: 0 | Q8: 0 | R8: 0 | S8: 0 | T8: =SUM(O8:S8) -> 0 | U8: 1 | V8: 0 | W8: 0 | X8: 0 | Y8: 1 | Z8: =SUM(U8:Y8) -> 2 | AA8: 0 | AB8: 0 | AC8: 0 | AD8: 0 | AE8: 0 | AF8: =SUM(AA8:AE8) -> 0 | AG8: 0 | AH8: 1 | AI8: 0 | AJ8: 0 | AK8: 0 | AL8: =SUM(AG8:AK8) -> 1 | AM8: =H8+N8+T8+Z8+AF8+AL8 -> 3 | AN8: =IF(AM8=0,"Conforme",IF(AM8<=12,"Atenção","Crítico")) -> Atenção
A9: HU07 | B9: [Federal Spending] Como desenvolvedor, quero atualizar a tabela de regras de validação do Broker para contemplar as atualizações de regras do DB-2213. | C9: 1 | D9: 0 | E9: 0 | F9: 0 | G9: 0 | H9: =SUM(C9:G9) -> 1 | I9: 0 | J9: 0 | K9: 0 | L9: 0 | M9: 0 | N9: =SUM(I9:M9) -> 0 | O9: 0 | P9: 0 | Q9: 0 | R9: 0 | S9: 0 | T9: =SUM(O9:S9) -> 0 | U9: 0 | V9: 0 | W9: 0 | X9: 0 | Y9: 0 | Z9: =SUM(U9:Y9) -> 0 | AA9: 0 | AB9: 0 | AC9: 0 | AD9: 0 | AE9: 0 | AF9: =SUM(AA9:AE9) -> 0 | AG9: 0 | AH9: 0 | AI9: 0 | AJ9: 0 | AK9: 0 | AL9: =SUM(AG9:AK9) -> 0 | AM9: =H9+N9+T9+Z9+AF9+AL9 -> 1 | AN9: =IF(AM9=0,"Conforme",IF(AM9<=12,"Atenção","Crítico")) -> Atenção
A10: HU08 | B10: [Federal Spending] Como usuário do site, quero ver dados de assistência financeira atualizados diariamente. | C10: 0 | D10: 0 | E10: 0 | F10: 0 | G10: 0 | H10: =SUM(C10:G10) -> 0 | I10: 0 | J10: 0 | K10: 0 | L10: 0 | M10: 0 | N10: =SUM(I10:M10) -> 0 | O10: 0 | P10: 0 | Q10: 0 | R10: 0 | S10: 0 | T10: =SUM(O10:S10) -> 0 | U10: 0 | V10: 0 | W10: 1 | X10: 0 | Y10: 0 | Z10: =SUM(U10:Y10) -> 1 | AA10: 0 | AB10: 0 | AC10: 0 | AD10: 0 | AE10: 0 | AF10: =SUM(AA10:AE10) -> 0 | AG10: 0 | AH10: 0 | AI10: 0 | AJ10: 0 | AK10: 0 | AL10: =SUM(AG10:AK10) -> 0 | AM10: =H10+N10+T10+Z10+AF10+AL10 -> 1 | AN10: =IF(AM10=0,"Conforme",IF(AM10<=12,"Atenção","Crítico")) -> Atenção
A11: HU09 | B11: [Federal Spending] Como proprietário, quero garantir que o USAspending envie apenas registros de concessão ao meu sistema. | C11: 0 | D11: 0 | E11: 1 | F11: 0 | G11: 0 | H11: =SUM(C11:G11) -> 1 | I11: 0 | J11: 0 | K11: 0 | L11: 0 | M11: 0 | N11: =SUM(I11:M11) -> 0 | O11: 0 | P11: 0 | Q11: 0 | R11: 0 | S11: 0 | T11: =SUM(O11:S11) -> 0 | U11: 0 | V11: 0 | W11: 0 | X11: 1 | Y11: 0 | Z11: =SUM(U11:Y11) -> 1 | AA11: 0 | AB11: 0 | AC11: 0 | AD11: 0 | AE11: 0 | AF11: =SUM(AA11:AE11) -> 0 | AG11: 0 | AH11: 0 | AI11: 0 | AJ11: 0 | AK11: 0 | AL11: =SUM(AG11:AK11) -> 0 | AM11: =H11+N11+T11+Z11+AF11+AL11 -> 2 | AN11: =IF(AM11=0,"Conforme",IF(AM11<=12,"Atenção","Crítico")) -> Atenção
A12: HU10 | B12: [Federal Spending] Como usuário do broker, quero ajudar a criar mockups de conteúdo, para que eu possa enviar meus dados eficientemente. | C12: 0 | D12: 0 | E12: 0 | F12: 1 | G12: 0 | H12: =SUM(C12:G12) -> 1 | I12: 0 | J12: 0 | K12: 0 | L12: 0 | M12: 0 | N12: =SUM(I12:M12) -> 0 | O12: 0 | P12: 0 | Q12: 0 | R12: 0 | S12: 0 | T12: =SUM(O12:S12) -> 0 | U12: 0 | V12: 0 | W12: 0 | X12: 0 | Y12: 0 | Z12: =SUM(U12:Y12) -> 0 | AA12: 0 | AB12: 0 | AC12: 0 | AD12: 0 | AE12: 0 | AF12: =SUM(AA12:AE12) -> 0 | AG12: 0 | AH12: 0 | AI12: 0 | AJ12: 0 | AK12: 0 | AL12: =SUM(AG12:AK12) -> 0 | AM12: =H12+N12+T12+Z12+AF12+AL12 -> 1 | AN12: =IF(AM12=0,"Conforme",IF(AM12<=12,"Atenção","Crítico")) -> Atenção
A13: HU11 | B13: [Recycling] Como usuário, quero inserir meu CEP e obter uma lista de instalações de reciclagem próximas, para que eu possa decidir quais considerar. | C13: 0 | D13: 0 | E13: 0 | F13: 0 | G13: 0 | H13: =SUM(C13:G13) -> 0 | I13: 0 | J13: 0 | K13: 0 | L13: 0 | M13: 0 | N13: =SUM(I13:M13) -> 0 | O13: 0 | P13: 0 | Q13: 0 | R13: 0 | S13: 0 | T13: =SUM(O13:S13) -> 0 | U13: 0 | V13: 0 | W13: 0 | X13: 0 | Y13: 0 | Z13: =SUM(U13:Y13) -> 0 | AA13: 0 | AB13: 0 | AC13: 0 | AD13: 0 | AE13: 0 | AF13: =SUM(AA13:AE13) -> 0 | AG13: 0 | AH13: 0 | AI13: 0 | AJ13: 0 | AK13: 0 | AL13: =SUM(AG13:AK13) -> 0 | AM13: =H13+N13+T13+Z13+AF13+AL13 -> 0 | AN13: =IF(AM13=0,"Conforme",IF(AM13<=12,"Atenção","Crítico")) -> Conforme
A14: HU12 | B14: [Recycling] Como usuário, quero obter o horário de funcionamento de cada instalação de reciclagem, para que eu possa agendar entregas em meus dias de folga ou após o trabalho. | C14: 0 | D14: 0 | E14: 0 | F14: 0 | G14: 0 | H14: =SUM(C14:G14) -> 0 | I14: 0 | J14: 0 | K14: 0 | L14: 0 | M14: 0 | N14: =SUM(I14:M14) -> 0 | O14: 0 | P14: 0 | Q14: 0 | R14: 0 | S14: 0 | T14: =SUM(O14:S14) -> 0 | U14: 0 | V14: 0 | W14: 0 | X14: 0 | Y14: 0 | Z14: =SUM(U14:Y14) -> 0 | AA14: 0 | AB14: 0 | AC14: 0 | AD14: 0 | AE14: 0 | AF14: =SUM(AA14:AE14) -> 0 | AG14: 0 | AH14: 0 | AI14: 0 | AJ14: 0 | AK14: 0 | AL14: =SUM(AG14:AK14) -> 0 | AM14: =H14+N14+T14+Z14+AF14+AL14 -> 0 | AN14: =IF(AM14=0,"Conforme",IF(AM14<=12,"Atenção","Crítico")) -> Conforme
... A32: HU30 | B32: [Planning Poker] Como Mike, quero ver algumas métricas sobre o uso do jogo, para ver o quanto ele está sendo utilizado. | C32: 0 | D32: 0 | E32: 0 | F32: 0 | G32: 0 | H32: =SUM(C32:G32) -> 0 | I32: 0 | J32: 0 | K32: 0 | L32: 0 | M32: 0 | N32: =SUM(I32:M32) -> 0 | O32: 0 | P32: 0 | Q32: 0 | R32: 0 | S32: 1 | T32: =SUM(O32:S32) -> 1 | U32: 0 | V32: 0 | W32: 0 | X32: 0 | Y32: 0 | Z32: =SUM(U32:Y32) -> 0 | AA32: 0 | AB32: 0 | AC32: 0 | AD32: 0 | AE32: 0 | AF32: =SUM(AA32:AE32) -> 0 | AG32: 0 | AH32: 0 | AI32: 0 | AJ32: 0 | AK32: 0 | AL32: =SUM(AG32:AK32) -> 0 | AM32: =H32+N32+T32+Z32+AF32+AL32 -> 1 | AN32: =IF(AM32=0,"Conforme",IF(AM32<=12,"Atenção","Crítico")) -> Atenção

Sheet Gemini_FewShot
A1: Avaliação de Requirements Smells — Gemini FewShot
A2: HU | B2: Descrição | C2: I-1 | D2: I-2 | E2: I-3 | F2: I-4 | G2: I-5 | H2: I_Count | I2: N-1 | J2: N-2 | K2: N-3 | L2: N-4 | M2: N-5 | N2: N_Count | O2: V-1 | P2: V-2 | Q2: V-3 | R2: V-4 | S2: V-5 | T2: V_Count | U2: E-1 | V2: E-2 | W2: E-3 | X2: E-4 | Y2: E-5 | Z2: E_Count | AA2: S-1 | AB2: S-2 | AC2: S-3 | AD2: S-4 | AE2: S-5 | AF2: S_Count | AG2: T-1 | AH2: T-2 | AI2: T-3 | AJ2: T-4 | AK2: T-5 | AL2: T_Count | AM2: Total_Smells | AN2: Nível
A3: HU01 | B3: [Federal Spending] Como usuário, quero que o botão de publicar no FABS seja desativado após clicar, enquanto as derivações acontecem, para que eu não possa clicar múltiplas vezes na mesma submissão. | C3: 0 | D3: 0 | E3: 0 | F3: 0 | G3: 0 | H3: =SUM(C3:G3) -> 0 | I3: 0 | J3: 1 | K3: 0 | L3: 0 | M3: 1 | N3: =SUM(I3:M3) -> 2 | O3: 0 | P3: 0 | Q3: 0 | R3: 0 | S3: 0 | T3: =SUM(O3:S3) -> 0 | U3: 0 | V3: 0 | W3: 0 | X3: 0 | Y3: 0 | Z3: =SUM(U3:Y3) -> 0 | AA3: 0 | AB3: 0 | AC3: 0 | AD3: 0 | AE3: 0 | AF3: =SUM(AA3:AE3) -> 0 | AG3: 1 | AH3: 1 | AI3: 1 | AJ3: 0 | AK3: 0 | AL3: =SUM(AG3:AK3) -> 3 | AM3: =H3+N3+T3+Z3+AF3+AL3 -> 5 | AN3: =IF(AM3=0,"Conforme",IF(AM3<=12,"Atenção","Crítico")) -> Atenção
A4: HU02 | B4: [Federal Spending] Como usuário de agência, quero enviar meus dados com campos cercados por aspas, para que o Excel não remova zeros à esquerda ou à direita. | C4: 0 | D4: 0 | E4: 0 | F4: 0 | G4: 0 | H4: =SUM(C4:G4) -> 0 | I4: 0 | J4: 0 | K4: 1 | L4: 0 | M4: 0 | N4: =SUM(I4:M4) -> 1 | O4: 0 | P4: 0 | Q4: 0 | R4: 0 | S4: 0 | T4: =SUM(O4:S4) -> 0 | U4: 0 | V4: 0 | W4: 0 | X4: 0 | Y4: 0 | Z4: =SUM(U4:Y4) -> 0 | AA4: 0 | AB4: 0 | AC4: 0 | AD4: 0 | AE4: 0 | AF4: =SUM(AA4:AE4) -> 0 | AG4: 1 | AH4: 0 | AI4: 1 | AJ4: 1 | AK4: 1 | AL4: =SUM(AG4:AK4) -> 4 | AM4: =H4+N4+T4+Z4+AF4+AL4 -> 5 | AN4: =IF(AM4=0,"Conforme",IF(AM4<=12,"Atenção","Crítico")) -> Atenção
A5: HU03 | B5: [Federal Spending] Como usuário do site, quero acessar os arquivos publicados pelo FABS, para que eu possa ver os novos arquivos conforme chegam. | C5: 0 | D5: 0 | E5: 0 | F5: 0 | G5: 0 | H5: =SUM(C5:G5) -> 0 | I5: 0 | J5: 0 | K5: 0 | L5: 0 | M5: 0 | N5: =SUM(I5:M5) -> 0 | O5: 0 | P5: 0 | Q5: 0 | R5: 0 | S5: 1 | T5: =SUM(O5:S5) -> 1 | U5: 0 | V5: 0 | W5: 0 | X5: 0 | Y5: 0 | Z5: =SUM(U5:Y5) -> 0 | AA5: 0 | AB5: 0 | AC5: 0 | AD5: 0 | AE5: 0 | AF5: =SUM(AA5:AE5) -> 0 | AG5: 1 | AH5: 0 | AI5: 1 | AJ5: 1 | AK5: 1 | AL5: =SUM(AG5:AK5) -> 4 | AM5: =H5+N5+T5+Z5+AF5+AL5 -> 5 | AN5: =IF(AM5=0,"Conforme",IF(AM5<=12,"Atenção","Crítico")) -> Atenção
A6: HU04 | B6: [Federal Spending] Como usuário da agência, quero receber um erro de arquivo mais útil ao enviar um arquivo com extensão incorreta. | C6: 0 | D6: 0 | E6: 0 | F6: 0 | G6: 0 | H6: =SUM(C6:G6) -> 0 | I6: 0 | J6: 0 | K6: 0 | L6: 0 | M6: 0 | N6: =SUM(I6:M6) -> 0 | O6: 1 | P6: 0 | Q6: 0 | R6: 0 | S6: 0 | T6: =SUM(O6:S6) -> 1 | U6: 0 | V6: 0 | W6: 0 | X6: 0 | Y6: 0 | Z6: =SUM(U6:Y6) -> 0 | AA6: 0 | AB6: 0 | AC6: 0 | AD6: 0 | AE6: 0 | AF6: =SUM(AA6:AE6) -> 0 | AG6: 1 | AH6: 0 | AI6: 1 | AJ6: 1 | AK6: 1 | AL6: =SUM(AG6:AK6) -> 4 | AM6: =H6+N6+T6+Z6+AF6+AL6 -> 5 | AN6: =IF(AM6=0,"Conforme",IF(AM6<=12,"Atenção","Crítico")) -> Atenção
A7: HU05 | B7: [Federal Spending] Como desenvolvedor, quero que as requisições de geração de arquivos D sejam gerenciadas e armazenadas em cache, para que requisições duplicadas não causem problemas de desempenho. | C7: 0 | D7: 0 | E7: 0 | F7: 0 | G7: 1 | H7: =SUM(C7:G7) -> 1 | I7: 0 | J7: 0 | K7: 0 | L7: 1 | M7: 0 | N7: =SUM(I7:M7) -> 1 | O7: 0 | P7: 1 | Q7: 0 | R7: 0 | S7: 0 | T7: =SUM(O7:S7) -> 1 | U7: 0 | V7: 0 | W7: 0 | X7: 0 | Y7: 0 | Z7: =SUM(U7:Y7) -> 0 | AA7: 0 | AB7: 0 | AC7: 0 | AD7: 0 | AE7: 0 | AF7: =SUM(AA7:AE7) -> 0 | AG7: 1 | AH7: 1 | AI7: 1 | AJ7: 1 | AK7: 1 | AL7: =SUM(AG7:AK7) -> 5 | AM7: =H7+N7+T7+Z7+AF7+AL7 -> 8 | AN7: =IF(AM7=0,"Conforme",IF(AM7<=12,"Atenção","Crítico")) -> Atenção
A8: HU06 | B8: [Federal Spending] Como usuário de agência, quero incluir um grande número de campos flexíveis sem impacto no desempenho. | C8: 0 | D8: 0 | E8: 0 | F8: 0 | G8: 0 | H8: =SUM(C8:G8) -> 0 | I8: 0 | J8: 0 | K8: 0 | L8: 0 | M8: 0 | N8: =SUM(I8:M8) -> 0 | O8: 1 | P8: 0 | Q8: 0 | R8: 0 | S8: 0 | T8: =SUM(O8:S8) -> 1 | U8: 1 | V8: 1 | W8: 0 | X8: 0 | Y8: 0 | Z8: =SUM(U8:Y8) -> 2 | AA8: 0 | AB8: 0 | AC8: 0 | AD8: 0 | AE8: 0 | AF8: =SUM(AA8:AE8) -> 0 | AG8: 1 | AH8: 1 | AI8: 1 | AJ8: 1 | AK8: 1 | AL8: =SUM(AG8:AK8) -> 5 | AM8: =H8+N8+T8+Z8+AF8+AL8 -> 8 | AN8: =IF(AM8=0,"Conforme",IF(AM8<=12,"Atenção","Crítico")) -> Atenção
A9: HU07 | B9: [Federal Spending] Como desenvolvedor, quero atualizar a tabela de regras de validação do Broker para contemplar as atualizações de regras do DB-2213. | C9: 1 | D9: 0 | E9: 0 | F9: 0 | G9: 0 | H9: =SUM(C9:G9) -> 1 | I9: 0 | J9: 0 | K9: 0 | L9: 0 | M9: 0 | N9: =SUM(I9:M9) -> 0 | O9: 1 | P9: 1 | Q9: 0 | R9: 0 | S9: 0 | T9: =SUM(O9:S9) -> 2 | U9: 0 | V9: 0 | W9: 0 | X9: 0 | Y9: 0 | Z9: =SUM(U9:Y9) -> 0 | AA9: 0 | AB9: 0 | AC9: 0 | AD9: 0 | AE9: 0 | AF9: =SUM(AA9:AE9) -> 0 | AG9: 1 | AH9: 0 | AI9: 1 | AJ9: 1 | AK9: 1 | AL9: =SUM(AG9:AK9) -> 4 | AM9: =H9+N9+T9+Z9+AF9+AL9 -> 7 | AN9: =IF(AM9=0,"Conforme",IF(AM9<=12,"Atenção","Crítico")) -> Atenção
A10: HU08 | B10: [Federal Spending] Como usuário do site, quero ver dados de assistência financeira atualizados diariamente. | C10: 0 | D10: 0 | E10: 0 | F10: 0 | G10: 0 | H10: =SUM(C10:G10) -> 0 | I10: 0 | J10: 0 | K10: 0 | L10: 0 | M10: 0 | N10: =SUM(I10:M10) -> 0 | O10: 1 | P10: 0 | Q10: 0 | R10: 0 | S10: 0 | T10: =SUM(O10:S10) -> 1 | U10: 0 | V10: 0 | W10: 1 | X10: 0 | Y10: 0 | Z10: =SUM(U10:Y10) -> 1 | AA10: 0 | AB10: 0 | AC10: 0 | AD10: 0 | AE10: 0 | AF10: =SUM(AA10:AE10) -> 0 | AG10: 1 | AH10: 0 | AI10: 1 | AJ10: 1 | AK10: 1 | AL10: =SUM(AG10:AK10) -> 4 | AM10: =H10+N10+T10+Z10+AF10+AL10 -> 6 | AN10: =IF(AM10=0,"Conforme",IF(AM10<=12,"Atenção","Crítico")) -> Atenção
A11: HU09 | B11: [Federal Spending] Como proprietário, quero garantir que o USAspending envie apenas registros de concessão ao meu sistema. | C11: 0 | D11: 0 | E11: 1 | F11: 0 | G11: 0 | H11: =SUM(C11:G11) -> 1 | I11: 0 | J11: 0 | K11: 0 | L11: 0 | M11: 0 | N11: =SUM(I11:M11) -> 0 | O11: 1 | P11: 0 | Q11: 0 | R11: 0 | S11: 0 | T11: =SUM(O11:S11) -> 1 | U11: 0 | V11: 0 | W11: 0 | X11: 1 | Y11: 0 | Z11: =SUM(U11:Y11) -> 1 | AA11: 0 | AB11: 0 | AC11: 0 | AD11: 0 | AE11: 0 | AF11: =SUM(AA11:AE11) -> 0 | AG11: 1 | AH11: 0 | AI11: 1 | AJ11: 1 | AK11: 1 | AL11: =SUM(AG11:AK11) -> 4 | AM11: =H11+N11+T11+Z11+AF11+AL11 -> 7 | AN11: =IF(AM11=0,"Conforme",IF(AM11<=12,"Atenção","Crítico")) -> Atenção
A12: HU10 | B12: [Federal Spending] Como usuário do broker, quero ajudar a criar mockups de conteúdo, para que eu possa enviar meus dados eficientemente. | C12: 0 | D12: 0 | E12: 0 | F12: 1 | G12: 0 | H12: =SUM(C12:G12) -> 1 | I12: 0 | J12: 0 | K12: 0 | L12: 0 | M12: 0 | N12: =SUM(I12:M12) -> 0 | O12: 0 | P12: 0 | Q12: 0 | R12: 0 | S12: 0 | T12: =SUM(O12:S12) -> 0 | U12: 1 | V12: 0 | W12: 0 | X12: 0 | Y12: 0 | Z12: =SUM(U12:Y12) -> 1 | AA12: 0 | AB12: 0 | AC12: 0 | AD12: 0 | AE12: 0 | AF12: =SUM(AA12:AE12) -> 0 | AG12: 1 | AH12: 1 | AI12: 1 | AJ12: 1 | AK12: 1 | AL12: =SUM(AG12:AK12) -> 5 | AM12: =H12+N12+T12+Z12+AF12+AL12 -> 7 | AN12: =IF(AM12=0,"Conforme",IF(AM12<=12,"Atenção","Crítico")) -> Atenção
A13: HU11 | B13: [Recycling] Como usuário, quero inserir meu CEP e obter uma lista de instalações de reciclagem próximas, para que eu possa decidir quais considerar. | C13: 0 | D13: 0 | E13: 0 | F13: 0 | G13: 0 | H13: =SUM(C13:G13) -> 0 | I13: 0 | J13: 0 | K13: 0 | L13: 0 | M13: 0 | N13: =SUM(I13:M13) -> 0 | O13: 0 | P13: 0 | Q13: 1 | R13: 0 | S13: 0 | T13: =SUM(O13:S13) -> 1 | U13: 1 | V13: 0 | W13: 0 | X13: 0 | Y13: 0 | Z13: =SUM(U13:Y13) -> 1 | AA13: 1 | AB13: 0 | AC13: 0 | AD13: 0 | AE13: 0 | AF13: =SUM(AA13:AE13) -> 1 | AG13: 1 | AH13: 1 | AI13: 1 | AJ13: 1 | AK13: 1 | AL13: =SUM(AG13:AK13) -> 5 | AM13: =H13+N13+T13+Z13+AF13+AL13 -> 8 | AN13: =IF(AM13=0,"Conforme",IF(AM13<=12,"Atenção","Crítico")) -> Atenção
